Workbook

Sheet vs 2019
A2: Negative Count | B2: =COUNTIF(B4:B252,"<0") -> 128 | C2: =COUNTIF(C4:C252,"<0") -> 68 | D2: =COUNTIF(D4:D252,"<0") -> 157 | E2: =COUNTIF(E4:E252,"<0") -> 123 | F2: =COUNTIF(F4:F252,"<0") -> 1 | G2: =COUNTIF(G4:G252,"<0") -> 1 | H2: =COUNTIF(H4:H252,"<0") -> 1 | I2: =COUNTIF(I4:I252,"<0") -> 1 | ... M2: =COUNTIF(M4:M252,"<0") -> 52
A3: Store ID | B3: _Vol Delta 1/2019 | C3: _Vol Delta 2/2019 | D3: _Vol Delta 3/2019 | E3: _Vol Delta 1Q2019 | F3: _P Delta 1/2019 | G3: _P Delta 2/2019 | H3: _P Delta 3/2019 | I3: _P Delta 1Q2019 | J3: Delta vs 1/2019 | K3: Delta vs 2/2019 | L3: Delta vs 3/2019 | M3: Delta vs 1Q2019
A4: AZ102 | B4: -5798.9736 | C4: -3212.0171 | D4: -9574.4781 | E4: -18585.469 | F4: 4745.4336 | G4: 5171.3871 | H4: 7126.7881 | I4: 17043.609 | J4: =SUM(B4,F4) -> -1053.54 | K4: =SUM(C4,G4) -> 1959.37 | L4: =SUM(D4,H4) -> -2447.69 | M4: =SUM(J4:L4) -> -1541.86
A5: AZ103 | B5: -2568.8395 | C5: 297.17 | D5: -18786.498 | E5: -21058.168 | F5: 10233.98 | G5: 10599.03 | H5: 13077.568 | I5: 33910.578 | J5: =SUM(B5,F5) -> 7665.14 | K5: =SUM(C5,G5) -> 10896.2 | L5: =SUM(D5,H5) -> -5708.93 | M5: =SUM(J5:L5) -> 12852.41
A6: AZ104 | B6: -5591.2227 | C6: 1158.2124 | D6: -8805.2029 | E6: -13238.213 | F6: 5068.5427 | G6: 5830.7476 | H6: 7333.3029 | I6: 18232.593 | J6: =SUM(B6,F6) -> -522.68 | K6: =SUM(C6,G6) -> 6988.96 | L6: =SUM(D6,H6) -> -1471.9 | M6: =SUM(J6:L6) -> 4994.38
A7: AZ105 | B7: -4925.26 | C7: -3029.09 | D7: -6633.61 | E7: -14587.96 | F7: 0 | G7: 0 | H7: 0 | I7: 0 | J7: =SUM(B7,F7) -> -4925.26 | K7: =SUM(C7,G7) -> -3029.09 | L7: =SUM(D7,H7) -> -6633.61 | M7: =SUM(J7:L7) -> -14587.96
A8: CA101 | B8: 0 | C8: 0 | D8: 0 | E8: 0 | F8: 0 | G8: 0 | H8: 0 | I8: 0 | J8: =SUM(B8,F8) -> 0 | K8: =SUM(C8,G8) -> 0 | L8: =SUM(D8,H8) -> 0 | M8: =SUM(J8:L8) -> 0
A9: CA102 | B9: 0 | C9: 0 | D9: 0 | E9: 0 | F9: 0 | G9: 0 | H9: 0 | I9: 0 | J9: =SUM(B9,F9) -> 0 | K9: =SUM(C9,G9) -> 0 | L9: =SUM(D9,H9) -> 0 | M9: =SUM(J9:L9) -> 0
A10: CA103 | B10: 13108.082 | C10: 30.255273 | D10: -19188.031 | E10: -6049.694 | F10: 4477.9782 | G10: 5096.6647 | H10: 5682.0611 | I10: 15256.704 | J10: =SUM(B10,F10) -> 17586.06 | K10: =SUM(C10,G10) -> 5126.92 | L10: =SUM(D10,H10) -> -13505.97 | M10: =SUM(J10:L10) -> 9207.01
A11: CA105 | B11: 0 | C11: 0 | D11: 0 | E11: 0 | F11: 0 | G11: 0 | H11: 0 | I11: 0 | J11: =SUM(B11,F11) -> 0 | K11: =SUM(C11,G11) -> 0 | L11: =SUM(D11,H11) -> 0 | M11: =SUM(J11:L11) -> 0
A12: CA106 | B12: -2089.63 | C12: 7350.0169 | D12: -18393.084 | E12: -13132.697 | F12: 15447.16 | G12: 16612.403 | H12: 18269.954 | I12: 50329.517 | J12: =SUM(B12,F12) -> 13357.53 | K12: =SUM(C12,G12) -> 23962.42 | L12: =SUM(D12,H12) -> -123.13 | M12: =SUM(J12:L12) -> 37196.82
A13: CA108 | B13: -5009.9584 | C13: 352.81772 | D13: -12399.471 | E13: -17056.612 | F13: 15293.678 | G13: 15967.082 | H13: 18059.271 | I13: 49320.032 | J13: =SUM(B13,F13) -> 10283.72 | K13: =SUM(C13,G13) -> 16319.9 | L13: =SUM(D13,H13) -> 5659.8 | M13: =SUM(J13:L13) -> 32263.42
A14: CA109 | B14: -7907.3058 | C14: -2534.6807 | D14: -9082.7693 | E14: -19524.756 | F14: 11257.186 | G14: 11653.961 | H14: 13595.119 | I14: 36506.266 | J14: =SUM(B14,F14) -> 3349.88 | K14: =SUM(C14,G14) -> 9119.28 | L14: =SUM(D14,H14) -> 4512.35 | M14: =SUM(J14:L14) -> 16981.51
A15: CA110 | B15: 11838.97 | C15: 16016.531 | D15: 2833.718 | E15: 30689.219 | F15: 12314.47 | G15: 12143.449 | H15: 16774.272 | I15: 41232.191 | J15: =SUM(B15,F15) -> 24153.44 | K15: =SUM(C15,G15) -> 28159.98 | L15: =SUM(D15,H15) -> 19607.99 | M15: =SUM(J15:L15) -> 71921.41
... A253: Grand Total | B253: -372590.24 | C253: 1070715.2 | D253: -1656326.1 | E253: -958201.14 | F253: 1465773.2 | G253: 1770440.1 | H253: 2234486.5 | I253: 5470699.8 | J253: =SUM(B253,F253) -> 1093183 | K253: =SUM(C253,G253) -> 2841155.3 | L253: =SUM(D253,H253) -> 578160.39 | M253: =SUM(J253:L253) -> 4512498.7

Sheet vs 2021
A2: Negative Count | B2: =COUNTIF(B4:B252,"<0") -> 17 | C2: =COUNTIF(C4:C252,"<0") -> 12 | D2: =COUNTIF(D4:D252,"<0") -> 17 | E2: =COUNTIF(E4:E252,"<0") -> 10 | F2: =COUNTIF(F4:F252,"<0") -> 0 | G2: =COUNTIF(G4:G252,"<0") -> 0 | H2: =COUNTIF(H4:H252,"<0") -> 0 | I2: =COUNTIF(I4:I252,"<0") -> 0 | ... M2: =COUNTIF(M4:M252,"<0") -> 2
A3: Store ID | B3: _Vol Delta 1/2021 | C3: _Vol Delta 2/2021 | D3: _Vol Delta 3/2021 | E3: _Vol Delta 1Q2021 | F3: _P Delta 1/2021 | G3: _P Delta 2/2021 | H3: _P Delta 3/2021 | I3: _P Delta 1Q2021 | J3: Delta vs 1/2021 | K3: Delta vs 2/2021 | L3: Delta vs 3/2021 | M3: Delta vs 1Q2021
A4: AZ102 | B4: 8340.2308 | C4: 7680.7317 | D4: 7667.8905 | E4: 23688.853 | F4: 1294.2092 | G4: 1410.3783 | H4: 1943.6695 | I4: 4648.2569 | J4: =SUM(B4,F4) -> 9634.44 | K4: =SUM(C4,G4) -> 9091.11 | L4: =SUM(D4,H4) -> 9611.56 | M4: =SUM(J4:L4) -> 28337.11
A5: AZ103 | B5: 12613.876 | C5: 12881.3 | D5: 13021.063 | E5: 38516.239 | F5: 5510.6044 | G5: 3261.24 | H5: 4023.8671 | I5: 12795.711 | J5: =SUM(B5,F5) -> 18124.48 | K5: =SUM(C5,G5) -> 16142.54 | L5: =SUM(D5,H5) -> 17044.93 | M5: =SUM(J5:L5) -> 51311.95
A6: AZ104 | B6: 3565.3902 | C6: 4730.3061 | D6: 4228.0083 | E6: 12523.705 | F6: 1382.3298 | G6: 1590.2039 | H6: 1999.9917 | I6: 4972.5254 | J6: =SUM(B6,F6) -> 4947.72 | K6: =SUM(C6,G6) -> 6320.51 | L6: =SUM(D6,H6) -> 6228 | M6: =SUM(J6:L6) -> 17496.23
A7: AZ105 | B7: 3496.37 | C7: 4645.92 | D7: 4630.55 | E7: 12772.84 | F7: 0 | G7: 0 | H7: 0 | I7: 0 | J7: =SUM(B7,F7) -> 3496.37 | K7: =SUM(C7,G7) -> 4645.92 | L7: =SUM(D7,H7) -> 4630.55 | M7: =SUM(J7:L7) -> 12772.84
A8: CA101 | B8: 0 | C8: 0 | D8: 0 | E8: 0 | F8: 0 | G8: 0 | H8: 0 | I8: 0 | J8: =SUM(B8,F8) -> 0 | K8: =SUM(C8,G8) -> 0 | L8: =SUM(D8,H8) -> 0 | M8: =SUM(J8:L8) -> 0
A9: CA102 | B9: 0 | C9: 0 | D9: 0 | E9: 0 | F9: 0 | G9: 0 | H9: 0 | I9: 0 | J9: =SUM(B9,F9) -> 0 | K9: =SUM(C9,G9) -> 0 | L9: =SUM(D9,H9) -> 0 | M9: =SUM(J9:L9) -> 0
A10: CA103 | B10: 10596.303 | C10: 14554.517 | D10: 14800.302 | E10: 39951.122 | F10: 559.74727 | G10: 637.08309 | H10: 710.25764 | I10: 1907.088 | J10: =SUM(B10,F10) -> 11156.05 | K10: =SUM(C10,G10) -> 15191.6 | L10: =SUM(D10,H10) -> 15510.56 | M10: =SUM(J10:L10) -> 41858.21
A11: CA105 | B11: 0 | C11: 0 | D11: 0 | E11: 0 | F11: 0 | G11: 0 | H11: 0 | I11: 0 | J11: =SUM(B11,F11) -> 0 | K11: =SUM(C11,G11) -> 0 | L11: =SUM(D11,H11) -> 0 | M11: =SUM(J11:L11) -> 0
A12: CA106 | B12: 15624.916 | C12: 15631.278 | D12: 7390.73 | E12: 38646.924 | F12: 10040.654 | G12: 10798.062 | H12: 11875.47 | I12: 32714.186 | J12: =SUM(B12,F12) -> 25665.57 | K12: =SUM(C12,G12) -> 26429.34 | L12: =SUM(D12,H12) -> 19266.2 | M12: =SUM(J12:L12) -> 71361.11
A13: CA108 | B13: 15375.065 | C13: 13699.882 | D13: 12576.443 | E13: 41651.39 | F13: 7930.0554 | G13: 8279.2278 | H13: 9364.0666 | I13: 25573.35 | J13: =SUM(B13,F13) -> 23305.12 | K13: =SUM(C13,G13) -> 21979.11 | L13: =SUM(D13,H13) -> 21940.51 | M13: =SUM(J13:L13) -> 67224.74
A14: CA109 | B14: 51595.435 | C14: 53413.986 | D14: 62310.964 | E14: 167320.38 | F14: 3752.3953 | G14: 3884.6536 | H14: 4531.7064 | I14: 12168.755 | J14: =SUM(B14,F14) -> 55347.83 | K14: =SUM(C14,G14) -> 57298.64 | L14: =SUM(D14,H14) -> 66842.67 | M14: =SUM(J14:L14) -> 179489.14
A15: CA110 | B15: 15335.848 | C15: 14630.881 | D15: 12590.712 | E15: 42557.442 | F15: 5683.6016 | G15: 5604.6687 | H15: 9435.528 | I15: 20723.798 | J15: =SUM(B15,F15) -> 21019.45 | K15: =SUM(C15,G15) -> 20235.55 | L15: =SUM(D15,H15) -> 22026.24 | M15: =SUM(J15:L15) -> 63281.24
... A253: Grand Total | B253: 2214856.2 | C253: 2384435.1 | D253: 2177160 | E253: 6776451.4 | F253: 698331.74 | G253: 927327.26 | H253: 1239399.2 | I253: 2865058.2 | J253: =SUM(B253,F253) -> 2913187.9 | K253: =SUM(C253,G253) -> 3311762.4 | L253: =SUM(D253,H253) -> 3416559.2 | M253: =SUM(J253:L253) -> 9641509.6

Sheet Summary
F1: 2 | G1: 3 | H1: 4 | J1: 5 | K1: 6 | L1: 2 | M1: 3 | N1: 4 | P1: 5 | Q1: 6 | V1: 1 | W1: 2 | X1: 3 | Y1: 4 | Z1: 5 | AA1: 6
A2: 2025 | B2: December | W2: PTD | X2: PTD | Y2: PTD | Z2: Volume | AA2: Price
K3: UNIT: $ | W3: 2022 | X3: 2023 | Y3: 2024 | Z3: vs 2023
A4: PTD | B4: SSS | F4: MTD Sales | I4: vs 2024 | L4: YTD Sales | O4: vs 2024 | S4: PTD | T4: YTD | V4: January | W4: 2 | X4: 15 | Y4: 28 | Z4: 93 | AA4: 106
A5: StoreID | B5: 2023 | C5: 2024 | D5: 2025 | F5: 2023 | G5: 2024 | H5: 2025 | I5: Variance | J5: Volume | K5: Price | L5: 2023 | M5: 2024 | N5: 2025 | O5: Variance | P5: Volume | Q5: Price | S5: TEST | T5: TEST | V5: February | W5: 3 | X5: 16 | Y5: 29 | Z5: 94 | AA5: 107
A6: AZ102 | B6: =IF(F6>0,"O","X") -> X | C6: =IF(G6>0,"O","X") -> X | D6: =IF(H6>0,"O","X") -> X | E6: CLOSED | F6: =VLOOKUP($A:$A,Data_sheet_PTD!$M:$DZ,VLOOKUP($B$2,Summary!$V$4:$AA$15,F$1,0),0) -> 0 | G6: =VLOOKUP($A:$A,Data_sheet_PTD!$M:$DZ,VLOOKUP($B$2,Summary!$V$4:$AA$15,G$1,0),0) -> 0 | H6: =VLOOKUP($A:$A,Data_sheet_PTD!$M:$DZ,VLOOKUP($B$2,Summary!$V$4:$AA$15,H$1,0),0) -> 0 | I6: =H6-G6 -> 0 | J6: =VLOOKUP($A:$A,Data_sheet_PTD!$M:$DZ,VLOOKUP($B$2,Summary!$V$4:$AA$15,J$1,0),0) -> 0 | K6: =VLOOKUP($A:$A,Data_sheet_PTD!$M:$DZ,VLOOKUP($B$2,Summary!$V$4:$AA$15,K$1,0),0) -> 0 | L6: =VLOOKUP($A:$A,Data_sheet_YTD!$M:$DZ,VLOOKUP($B$2,Summary!$V$4:$AA$15,L$1,0),0) -> 0 | M6: =VLOOKUP($A:$A,Data_sheet_YTD!$M:$DZ,VLOOKUP($B$2,Summary!$V$4:$AA$15,M$1,0),0) -> 0 | N6: =VLOOKUP($A:$A,Data_sheet_YTD!$M:$DZ,VLOOKUP($B$2,Summary!$V$4:$AA$15,N$1,0),0) -> 0 | O6: =N6-M6 -> 0 | P6: =VLOOKUP($A:$A,Data_sheet_YTD!$M:$DZ,VLOOKUP($B$2,Summary!$V$4:$AA$15,P$1,0),0) -> 0 | Q6: =VLOOKUP($A:$A,Data_sheet_YTD!$M:$DZ,VLOOKUP($B$2,Summary!$V$4:$AA$15,Q$1,0),0) -> 0 | R6: 0 | S6: =I6-J6-K6 -> 0 | T6: =O6-P6-Q6 -> 0 | V6: March | W6: 4 | X6: 17 | Y6: 30 | Z6: 95 | AA6: 108
A7: AZ103 | B7: =IF(F7>0,"O","X") -> O | C7: =IF(G7>0,"O","X") -> O | D7: =IF(H7>0,"O","X") -> O | E7: OPEN | F7: =VLOOKUP($A:$A,Data_sheet_PTD!$M:$DZ,VLOOKUP($B$2,Summary!$V$4:$AA$15,F$1,0),0) -> 40125.18 | G7: =VLOOKUP($A:$A,Data_sheet_PTD!$M:$DZ,VLOOKUP($B$2,Summary!$V$4:$AA$15,G$1,0),0) -> 53617.92 | H7: =VLOOKUP($A:$A,Data_sheet_PTD!$M:$DZ,VLOOKUP($B$2,Summary!$V$4:$AA$15,H$1,0),0) -> 58017.83 | I7: =H7-G7 -> 4399.91 | J7: =VLOOKUP($A:$A,Data_sheet_PTD!$M:$DZ,VLOOKUP($B$2,Summary!$V$4:$AA$15,J$1,0),0) -> 4399.91 | K7: =VLOOKUP($A:$A,Data_sheet_PTD!$M:$DZ,VLOOKUP($B$2,Summary!$V$4:$AA$15,K$1,0),0) -> 0 | L7: =VLOOKUP($A:$A,Data_sheet_YTD!$M:$DZ,VLOOKUP($B$2,Summary!$V$4:$AA$15,L$1,0),0) -> 845698.64 | M7: =VLOOKUP($A:$A,Data_sheet_YTD!$M:$DZ,VLOOKUP($B$2,Summary!$V$4:$AA$15,M$1,0),0) -> 1003308.2 | N7: =VLOOKUP($A:$A,Data_sheet_YTD!$M:$DZ,VLOOKUP($B$2,Summary!$V$4:$AA$15,N$1,0),0) -> 1051113.7 | O7: =N7-M7 -> 47805.47 | P7: =VLOOKUP($A:$A,Data_sheet_YTD!$M:$DZ,VLOOKUP($B$2,Summary!$V$4:$AA$15,P$1,0),0) -> 31628.44 | Q7: =VLOOKUP($A:$A,Data_sheet_YTD!$M:$DZ,VLOOKUP($B$2,Summary!$V$4:$AA$15,Q$1,0),0) -> 16177.03 | R7: 16492.37 | S7: =R7-I7 -> 12092.46 | T7: =O7-P7-Q7 -> 1.0186341e-10 | V7: April | W7: 5 | X7: 18 | Y7: 31 | Z7: 96 | AA7: 109
A8: AZ104 | B8: =IF(F8>0,"O","X") -> O | C8: =IF(G8>0,"O","X") -> O | D8: =IF(H8>0,"O","X") -> O | E8: OPEN | F8: =VLOOKUP($A:$A,Data_sheet_PTD!$M:$DZ,VLOOKUP($B$2,Summary!$V$4:$AA$15,F$1,0),0) -> 26942.3 | G8: =VLOOKUP($A:$A,Data_sheet_PTD!$M:$DZ,VLOOKUP($B$2,Summary!$V$4:$AA$15,G$1,0),0) -> 36051.48 | H8: =VLOOKUP($A:$A,Data_sheet_PTD!$M:$DZ,VLOOKUP($B$2,Summary!$V$4:$AA$15,H$1,0),0) -> 33637.09 | I8: =H8-G8 -> -2414.39 | J8: =VLOOKUP($A:$A,Data_sheet_PTD!$M:$DZ,VLOOKUP($B$2,Summary!$V$4:$AA$15,J$1,0),0) -> -2414.39 | K8: =VLOOKUP($A:$A,Data_sheet_PTD!$M:$DZ,VLOOKUP($B$2,Summary!$V$4:$AA$15,K$1,0),0) -> 0 | L8: =VLOOKUP($A:$A,Data_sheet_YTD!$M:$DZ,VLOOKUP($B$2,Summary!$V$4:$AA$15,L$1,0),0) -> 442649.07 | M8: =VLOOKUP($A:$A,Data_sheet_YTD!$M:$DZ,VLOOKUP($B$2,Summary!$V$4:$AA$15,M$1,0),0) -> 532448.6 | N8: =VLOOKUP($A:$A,Data_sheet_YTD!$M:$DZ,VLOOKUP($B$2,Summary!$V$4:$AA$15,N$1,0),0) -> 538712.66 | O8: =N8-M8 -> 6264.06 | P8: =VLOOKUP($A:$A,Data_sheet_YTD!$M:$DZ,VLOOKUP($B$2,Summary!$V$4:$AA$15,P$1,0),0) -> -2195.8841 | Q8: =VLOOKUP($A:$A,Data_sheet_YTD!$M:$DZ,VLOOKUP($B$2,Summary!$V$4:$AA$15,Q$1,0),0) -> 8459.9441 | R8: 5373.19 | S8: =R8-I8 -> 7787.58 | T8: =O8-P8-Q8 -> 7.4578566e-11 | V8: May | W8: 6 | X8: 19 | Y8: 32 | Z8: 97 | AA8: 110
A9: AZ105 | B9: =IF(F9>0,"O","X") -> O | C9: =IF(G9>0,"O","X") -> O | D9: =IF(H9>0,"O","X") -> O | E9: OPEN | F9: =VLOOKUP($A:$A,Data_sheet_PTD!$M:$DZ,VLOOKUP($B$2,Summary!$V$4:$AA$15,F$1,0),0) -> 28321.69 | G9: =VLOOKUP($A:$A,Data_sheet_PTD!$M:$DZ,VLOOKUP($B$2,Summary!$V$4:$AA$15,G$1,0),0) -> 32140.71 | H9: =VLOOKUP($A:$A,Data_sheet_PTD!$M:$DZ,VLOOKUP($B$2,Summary!$V$4:$AA$15,H$1,0),0) -> 34502.49 | I9: =H9-G9 -> 2361.78 | J9: =VLOOKUP($A:$A,Data_sheet_PTD!$M:$DZ,VLOOKUP($B$2,Summary!$V$4:$AA$15,J$1,0),0) -> 2361.78 | K9: =VLOOKUP($A:$A,Data_sheet_PTD!$M:$DZ,VLOOKUP($B$2,Summary!$V$4:$AA$15,K$1,0),0) -> 0 | L9: =VLOOKUP($A:$A,Data_sheet_YTD!$M:$DZ,VLOOKUP($B$2,Summary!$V$4:$AA$15,L$1,0),0) -> 492584.47 | M9: =VLOOKUP($A:$A,Data_sheet_YTD!$M:$DZ,VLOOKUP($B$2,Summary!$V$4:$AA$15,M$1,0),0) -> 541112.17 | N9: =VLOOKUP($A:$A,Data_sheet_YTD!$M:$DZ,VLOOKUP($B$2,Summary!$V$4:$AA$15,N$1,0),0) -> 574231.18 | O9: =N9-M9 -> 33119.01 | P9: =VLOOKUP($A:$A,Data_sheet_YTD!$M:$DZ,VLOOKUP($B$2,Summary!$V$4:$AA$15,P$1,0),0) -> 24061.215 | Q9: =VLOOKUP($A:$A,Data_sheet_YTD!$M:$DZ,VLOOKUP($B$2,Summary!$V$4:$AA$15,Q$1,0),0) -> 9057.7948 | R9: 8540.52 | S9: =R9-I9 -> 6178.74 | T9: =O9-P9-Q9 -> -7.6397555e-11 | V9: June | W9: 7 | X9: 20 | Y9: 33 | Z9: 98 | AA9: 111
A10: AZ106 | B10: =IF(F10>0,"O","X") -> X | C10: =IF(G10>0,"O","X") -> X | D10: =IF(H10>0,"O","X") -> X | E10: CLOSED | F10: =VLOOKUP($A:$A,Data_sheet_PTD!$M:$DZ,VLOOKUP($B$2,Summary!$V$4:$AA$15,F$1,0),0) -> 0 | G10: =VLOOKUP($A:$A,Data_sheet_PTD!$M:$DZ,VLOOKUP($B$2,Summary!$V$4:$AA$15,G$1,0),0) -> 0 | H10: =VLOOKUP($A:$A,Data_sheet_PTD!$M:$DZ,VLOOKUP($B$2,Summary!$V$4:$AA$15,H$1,0),0) -> 0 | I10: =H10-G10 -> 0 | J10: =VLOOKUP($A:$A,Data_sheet_PTD!$M:$DZ,VLOOKUP($B$2,Summary!$V$4:$AA$15,J$1,0),0) -> 0 | K10: =VLOOKUP($A:$A,Data_sheet_PTD!$M:$DZ,VLOOKUP($B$2,Summary!$V$4:$AA$15,K$1,0),0) -> 0 | L10: =VLOOKUP($A:$A,Data_sheet_YTD!$M:$DZ,VLOOKUP($B$2,Summary!$V$4:$AA$15,L$1,0),0) -> 0 | M10: =VLOOKUP($A:$A,Data_sheet_YTD!$M:$DZ,VLOOKUP($B$2,Summary!$V$4:$AA$15,M$1,0),0) -> 0 | N10: =VLOOKUP($A:$A,Data_sheet_YTD!$M:$DZ,VLOOKUP($B$2,Summary!$V$4:$AA$15,N$1,0),0) -> 0 | O10: =N10-M10 -> 0 | P10: =VLOOKUP($A:$A,Data_sheet_YTD!$M:$DZ,VLOOKUP($B$2,Summary!$V$4:$AA$15,P$1,0),0) -> 0 | Q10: =VLOOKUP($A:$A,Data_sheet_YTD!$M:$DZ,VLOOKUP($B$2,Summary!$V$4:$AA$15,Q$1,0),0) -> 0 | R10: 0 | S10: =R10-I10 -> 0 | T10: =O10-P10-Q10 -> 0 | V10: July | W10: 8 | X10: 21 | Y10: 34 | Z10: 99 | AA10: 112
A11: CA101 | B11: =IF(F11>0,"O","X") -> X | C11: =IF(G11>0,"O","X") -> X | D11: =IF(H11>0,"O","X") -> X | E11: CLOSED | F11: =VLOOKUP($A:$A,Data_sheet_PTD!$M:$DZ,VLOOKUP($B$2,Summary!$V$4:$AA$15,F$1,0),0) -> 0 | G11: =VLOOKUP($A:$A,Data_sheet_PTD!$M:$DZ,VLOOKUP($B$2,Summary!$V$4:$AA$15,G$1,0),0) -> 0 | H11: =VLOOKUP($A:$A,Data_sheet_PTD!$M:$DZ,VLOOKUP($B$2,Summary!$V$4:$AA$15,H$1,0),0) -> 0 | I11: =H11-G11 -> 0 | J11: =VLOOKUP($A:$A,Data_sheet_PTD!$M:$DZ,VLOOKUP($B$2,Summary!$V$4:$AA$15,J$1,0),0) -> 0 | K11: =VLOOKUP($A:$A,Data_sheet_PTD!$M:$DZ,VLOOKUP($B$2,Summary!$V$4:$AA$15,K$1,0),0) -> 0 | L11: =VLOOKUP($A:$A,Data_sheet_YTD!$M:$DZ,VLOOKUP($B$2,Summary!$V$4:$AA$15,L$1,0),0) -> 0 | M11: =VLOOKUP($A:$A,Data_sheet_YTD!$M:$DZ,VLOOKUP($B$2,Summary!$V$4:$AA$15,M$1,0),0) -> 0 | N11: =VLOOKUP($A:$A,Data_sheet_YTD!$M:$DZ,VLOOKUP($B$2,Summary!$V$4:$AA$15,N$1,0),0) -> 0 | O11: =N11-M11 -> 0 | P11: =VLOOKUP($A:$A,Data_sheet_YTD!$M:$DZ,VLOOKUP($B$2,Summary!$V$4:$AA$15,P$1,0),0) -> 0 | Q11: =VLOOKUP($A:$A,Data_sheet_YTD!$M:$DZ,VLOOKUP($B$2,Summary!$V$4:$AA$15,Q$1,0),0) -> 0 | R11: 0 | S11: =R11-I11 -> 0 | T11: =O11-P11-Q11 -> 0 | V11: August | W11: 9 | X11: 22 | Y11: 35 | Z11: 100 | AA11: 113
A12: CA102 | B12: =IF(F12>0,"O","X") -> X | C12: =IF(G12>0,"O","X") -> X | D12: =IF(H12>0,"O","X") -> X | E12: CLOSED | F12: =VLOOKUP($A:$A,Data_sheet_PTD!$M:$DZ,VLOOKUP($B$2,Summary!$V$4:$AA$15,F$1,0),0) -> 0 | G12: =VLOOKUP($A:$A,Data_sheet_PTD!$M:$DZ,VLOOKUP($B$2,Summary!$V$4:$AA$15,G$1,0),0) -> 0 | H12: =VLOOKUP($A:$A,Data_sheet_PTD!$M:$DZ,VLOOKUP($B$2,Summary!$V$4:$AA$15,H$1,0),0) -> 0 | I12: =H12-G12 -> 0 | J12: =VLOOKUP($A:$A,Data_sheet_PTD!$M:$DZ,VLOOKUP($B$2,Summary!$V$4:$AA$15,J$1,0),0) -> 0 | K12: =VLOOKUP($A:$A,Data_sheet_PTD!$M:$DZ,VLOOKUP($B$2,Summary!$V$4:$AA$15,K$1,0),0) -> 0 | L12: =VLOOKUP($A:$A,Data_sheet_YTD!$M:$DZ,VLOOKUP($B$2,Summary!$V$4:$AA$15,L$1,0),0) -> 0 | M12: =VLOOKUP($A:$A,Data_sheet_YTD!$M:$DZ,VLOOKUP($B$2,Summary!$V$4:$AA$15,M$1,0),0) -> 0 | N12: =VLOOKUP($A:$A,Data_sheet_YTD!$M:$DZ,VLOOKUP($B$2,Summary!$V$4:$AA$15,N$1,0),0) -> 0 | O12: =N12-M12 -> 0 | P12: =VLOOKUP($A:$A,Data_sheet_YTD!$M:$DZ,VLOOKUP($B$2,Summary!$V$4:$AA$15,P$1,0),0) -> 0 | Q12: =VLOOKUP($A:$A,Data_sheet_YTD!$M:$DZ,VLOOKUP($B$2,Summary!$V$4:$AA$15,Q$1,0),0) -> 0 | R12: 0 | S12: =R12-I12 -> 0 | T12: =O12-P12-Q12 -> 0 | V12: September | W12: 10 | X12: 23 | Y12: 36 | Z12: 101 | AA12: 114
A13: CA103 | B13: =IF(F13>0,"O","X") -> X | C13: =IF(G13>0,"O","X") -> X | D13: =IF(H13>0,"O","X") -> X | E13: CLOSED | F13: =VLOOKUP($A:$A,Data_sheet_PTD!$M:$DZ,VLOOKUP($B$2,Summary!$V$4:$AA$15,F$1,0),0) -> 0 | G13: =VLOOKUP($A:$A,Data_sheet_PTD!$M:$DZ,VLOOKUP($B$2,Summary!$V$4:$AA$15,G$1,0),0) -> 0 | H13: =VLOOKUP($A:$A,Data_sheet_PTD!$M:$DZ,VLOOKUP($B$2,Summary!$V$4:$AA$15,H$1,0),0) -> 0 | I13: =H13-G13 -> 0 | J13: =VLOOKUP($A:$A,Data_sheet_PTD!$M:$DZ,VLOOKUP($B$2,Summary!$V$4:$AA$15,J$1,0),0) -> 0 | K13: =VLOOKUP($A:$A,Data_sheet_PTD!$M:$DZ,VLOOKUP($B$2,Summary!$V$4:$AA$15,K$1,0),0) -> 0 | L13: =VLOOKUP($A:$A,Data_sheet_YTD!$M:$DZ,VLOOKUP($B$2,Summary!$V$4:$AA$15,L$1,0),0) -> 26174.3 | M13: =VLOOKUP($A:$A,Data_sheet_YTD!$M:$DZ,VLOOKUP($B$2,Summary!$V$4:$AA$15,M$1,0),0) -> 0 | N13: =VLOOKUP($A:$A,Data_sheet_YTD!$M:$DZ,VLOOKUP($B$2,Summary!$V$4:$AA$15,N$1,0),0) -> 0 | O13: =N13-M13 -> 0 | P13: =VLOOKUP($A:$A,Data_sheet_YTD!$M:$DZ,VLOOKUP($B$2,Summary!$V$4:$AA$15,P$1,0),0) -> 0 | Q13: =VLOOKUP($A:$A,Data_sheet_YTD!$M:$DZ,VLOOKUP($B$2,Summary!$V$4:$AA$15,Q$1,0),0) -> 0 | R13: 0 | S13: =R13-I13 -> 0 | T13: =O13-P13-Q13 -> 0 | V13: October | W13: 11 | X13: 24 | Y13: 37 | Z13: 102 | AA13: 115
A14: CA105 | B14: =IF(F14>0,"O","X") -> X | C14: =IF(G14>0,"O","X") -> X | D14: =IF(H14>0,"O","X") -> X | E14: CLOSED | F14: =VLOOKUP($A:$A,Data_sheet_PTD!$M:$DZ,VLOOKUP($B$2,Summary!$V$4:$AA$15,F$1,0),0) -> 0 | G14: =VLOOKUP($A:$A,Data_sheet_PTD!$M:$DZ,VLOOKUP($B$2,Summary!$V$4:$AA$15,G$1,0),0) -> 0 | H14: =VLOOKUP($A:$A,Data_sheet_PTD!$M:$DZ,VLOOKUP($B$2,Summary!$V$4:$AA$15,H$1,0),0) -> 0 | I14: =H14-G14 -> 0 | J14: =VLOOKUP($A:$A,Data_sheet_PTD!$M:$DZ,VLOOKUP($B$2,Summary!$V$4:$AA$15,J$1,0),0) -> 0 | K14: =VLOOKUP($A:$A,Data_sheet_PTD!$M:$DZ,VLOOKUP($B$2,Summary!$V$4:$AA$15,K$1,0),0) -> 0 | L14: =VLOOKUP($A:$A,Data_sheet_YTD!$M:$DZ,VLOOKUP($B$2,Summary!$V$4:$AA$15,L$1,0),0) -> 0 | M14: =VLOOKUP($A:$A,Data_sheet_YTD!$M:$DZ,VLOOKUP($B$2,Summary!$V$4:$AA$15,M$1,0),0) -> 0 | N14: =VLOOKUP($A:$A,Data_sheet_YTD!$M:$DZ,VLOOKUP($B$2,Summary!$V$4:$AA$15,N$1,0),0) -> 0 | O14: =N14-M14 -> 0 | P14: =VLOOKUP($A:$A,Data_sheet_YTD!$M:$DZ,VLOOKUP($B$2,Summary!$V$4:$AA$15,P$1,0),0) -> 0 | Q14: =VLOOKUP($A:$A,Data_sheet_YTD!$M:$DZ,VLOOKUP($B$2,Summary!$V$4:$AA$15,Q$1,0),0) -> 0 | R14: 0 | S14: =R14-I14 -> 0 | T14: =O14-P14-Q14 -> 0 | V14: November | W14: 12 | X14: 25 | Y14: 38 | Z14: 103 | AA14: 116
A15: CA106 | B15: =IF(F15>0,"O","X") -> O | C15: =IF(G15>0,"O","X") -> O | D15: =IF(H15>0,"O","X") -> O | E15: OPEN | F15: =VLOOKUP($A:$A,Data_sheet_PTD!$M:$DZ,VLOOKUP($B$2,Summary!$V$4:$AA$15,F$1,0),0) -> 50798.23 | G15: =VLOOKUP($A:$A,Data_sheet_PTD!$M:$DZ,VLOOKUP($B$2,Summary!$V$4:$AA$15,G$1,0),0) -> 69224.17 | H15: =VLOOKUP($A:$A,Data_sheet_PTD!$M:$DZ,VLOOKUP($B$2,Summary!$V$4:$AA$15,H$1,0),0) -> 61579.08 | I15: =H15-G15 -> -7645.09 | J15: =VLOOKUP($A:$A,Data_sheet_PTD!$M:$DZ,VLOOKUP($B$2,Summary!$V$4:$AA$15,J$1,0),0) -> -14564.088 | K15: =VLOOKUP($A:$A,Data_sheet_PTD!$M:$DZ,VLOOKUP($B$2,Summary!$V$4:$AA$15,K$1,0),0) -> 6918.9978 | L15: =VLOOKUP($A:$A,Data_sheet_YTD!$M:$DZ,VLOOKUP($B$2,Summary!$V$4:$AA$15,L$1,0),0) -> 930117.39 | M15: =VLOOKUP($A:$A,Data_sheet_YTD!$M:$DZ,VLOOKUP($B$2,Summary!$V$4:$AA$15,M$1,0),0) -> 1185598.7 | N15: =VLOOKUP($A:$A,Data_sheet_YTD!$M:$DZ,VLOOKUP($B$2,Summary!$V$4:$AA$15,N$1,0),0) -> 1163682.4 | O15: =N15-M15 -> -21916.29 | P15: =VLOOKUP($A:$A,Data_sheet_YTD!$M:$DZ,VLOOKUP($B$2,Summary!$V$4:$AA$15,P$1,0),0) -> -87084.572 | Q15: =VLOOKUP($A:$A,Data_sheet_YTD!$M:$DZ,VLOOKUP($B$2,Summary!$V$4:$AA$15,Q$1,0),0) -> 65168.282 | R15: 8106.01 | S15: =R15-I15 -> 15751.1 | T15: =O15-P15-Q15 -> 1.891749e-10 | V15: December | W15: 13 | X15: 26 | Y15: 39 | Z15: 104 | AA15: 117
A16: CA107 | B16: =IF(F16>0,"O","X") -> X | C16: =IF(G16>0,"O","X") -> X | D16: =IF(H16>0,"O","X") -> X | E16: CLOSED | F16: =VLOOKUP($A:$A,Data_sheet_PTD!$M:$DZ,VLOOKUP($B$2,Summary!$V$4:$AA$15,F$1,0),0) -> 0 | G16: =VLOOKUP($A:$A,Data_sheet_PTD!$M:$DZ,VLOOKUP($B$2,Summary!$V$4:$AA$15,G$1,0),0) -> 0 | H16: =VLOOKUP($A:$A,Data_sheet_PTD!$M:$DZ,VLOOKUP($B$2,Summary!$V$4:$AA$15,H$1,0),0) -> 0 | I16: =H16-G16 -> 0 | J16: =VLOOKUP($A:$A,Data_sheet_PTD!$M:$DZ,VLOOKUP($B$2,Summary!$V$4:$AA$15,J$1,0),0) -> 0 | K16: =VLOOKUP($A:$A,Data_sheet_PTD!$M:$DZ,VLOOKUP($B$2,Summary!$V$4:$AA$15,K$1,0),0) -> 0 | L16: =VLOOKUP($A:$A,Data_sheet_YTD!$M:$DZ,VLOOKUP($B$2,Summary!$V$4:$AA$15,L$1,0),0) -> 0 | M16: =VLOOKUP($A:$A,Data_sheet_YTD!$M:$DZ,VLOOKUP($B$2,Summary!$V$4:$AA$15,M$1,0),0) -> 0 | N16: =VLOOKUP($A:$A,Data_sheet_YTD!$M:$DZ,VLOOKUP($B$2,Summary!$V$4:$AA$15,N$1,0),0) -> 0 | O16: =N16-M16 -> 0 | P16: =VLOOKUP($A:$A,Data_sheet_YTD!$M:$DZ,VLOOKUP($B$2,Summary!$V$4:$AA$15,P$1,0),0) -> 0 | Q16: =VLOOKUP($A:$A,Data_sheet_YTD!$M:$DZ,VLOOKUP($B$2,Summary!$V$4:$AA$15,Q$1,0),0) -> 0 | R16: 0 | S16: =R16-I16 -> 0 | T16: =O16-P16-Q16 -> 0
A17: CA108 | B17: =IF(F17>0,"O","X") -> O | C17: =IF(G17>0,"O","X") -> O | D17: =IF(H17>0,"O","X") -> O | E17: OPEN | F17: =VLOOKUP($A:$A,Data_sheet_PTD!$M:$DZ,VLOOKUP($B$2,Summary!$V$4:$AA$15,F$1,0),0) -> 30796.71 | G17: =VLOOKUP($A:$A,Data_sheet_PTD!$M:$DZ,VLOOKUP($B$2,Summary!$V$4:$AA$15,G$1,0),0) -> 35707.87 | H17: =VLOOKUP($A:$A,Data_sheet_PTD!$M:$DZ,VLOOKUP($B$2,Summary!$V$4:$AA$15,H$1,0),0) -> 33386.36 | I17: =H17-G17 -> -2321.51 | J17: =VLOOKUP($A:$A,Data_sheet_PTD!$M:$DZ,VLOOKUP($B$2,Summary!$V$4:$AA$15,J$1,0),0) -> -2766.6615 | K17: =VLOOKUP($A:$A,Data_sheet_PTD!$M:$DZ,VLOOKUP($B$2,Summary!$V$4:$AA$15,K$1,0),0) -> 445.15147 | L17: =VLOOKUP($A:$A,Data_sheet_YTD!$M:$DZ,VLOOKUP($B$2,Summary!$V$4:$AA$15,L$1,0),0) -> 536436.45 | M17: =VLOOKUP($A:$A,Data_sheet_YTD!$M:$DZ,VLOOKUP($B$2,Summary!$V$4:$AA$15,M$1,0),0) -> 633426.51 | N17: =VLOOKUP($A:$A,Data_sheet_YTD!$M:$DZ,VLOOKUP($B$2,Summary!$V$4:$AA$15,N$1,0),0) -> 600070.47 | O17: =N17-M17 -> -33356.04 | P17: =VLOOKUP($A:$A,Data_sheet_YTD!$M:$DZ,VLOOKUP($B$2,Summary!$V$4:$AA$15,P$1,0),0) -> -46647.535 | Q17: =VLOOKUP($A:$A,Data_sheet_YTD!$M:$DZ,VLOOKUP($B$2,Summary!$V$4:$AA$15,Q$1,0),0) -> 13291.495 | R17: 1229.91 | S17: =R17-I17 -> 3551.42 | T17: =O17-P17-Q17 -> -4.5474735e-11
A18: CA109 | B18: =IF(F18>0,"O","X") -> O | C18: =IF(G18>0,"O","X") -> O | D18: =IF(H18>0,"O","X") -> O | E18: OPEN | F18: =VLOOKUP($A:$A,Data_sheet_PTD!$M:$DZ,VLOOKUP($B$2,Summary!$V$4:$AA$15,F$1,0),0) -> 114117.13 | G18: =VLOOKUP($A:$A,Data_sheet_PTD!$M:$DZ,VLOOKUP($B$2,Summary!$V$4:$AA$15,G$1,0),0) -> 123774.01 | H18: =VLOOKUP($A:$A,Data_sheet_PTD!$M:$DZ,VLOOKUP($B$2,Summary!$V$4:$AA$15,H$1,0),0) -> 126845.89 | I18: =H18-G18 -> 3071.88 | J18: =VLOOKUP($A:$A,Data_sheet_PTD!$M:$DZ,VLOOKUP($B$2,Summary!$V$4:$AA$15,J$1,0),0) -> -5988.5407 | K18: =VLOOKUP($A:$A,Data_sheet_PTD!$M:$DZ,VLOOKUP($B$2,Summary!$V$4:$AA$15,K$1,0),0) -> 9060.4207 | L18: =VLOOKUP($A:$A,Data_sheet_YTD!$M:$DZ,VLOOKUP($B$2,Summary!$V$4:$AA$15,L$1,0),0) -> 992914.52 | M18: =VLOOKUP($A:$A,Data_sheet_YTD!$M:$DZ,VLOOKUP($B$2,Summary!$V$4:$AA$15,M$1,0),0) -> 1189155.2 | N18: =VLOOKUP($A:$A,Data_sheet_YTD!$M:$DZ,VLOOKUP($B$2,Summary!$V$4:$AA$15,N$1,0),0) -> 1231018.3 | O18: =N18-M18 -> 41863.14 | P18: =VLOOKUP($A:$A,Data_sheet_YTD!$M:$DZ,VLOOKUP($B$2,Summary!$V$4:$AA$15,P$1,0),0) -> 9271.1752 | Q18: =VLOOKUP($A:$A,Data_sheet_YTD!$M:$DZ,VLOOKUP($B$2,Summary!$V$4:$AA$15,Q$1,0),0) -> 32591.965 | R18: 9740.31 | S18: =R18-I18 -> 6668.43 | T18: =O18-P18-Q18 -> -4.3655746e-11
A19: CA110 | B19: =IF(F19>0,"O","X") -> O | C19: =IF(G19>0,"O","X") -> O | D19: =IF(H19>0,"O","X") -> O | E19: OPEN | F19: =VLOOKUP($A:$A,Data_sheet_PTD!$M:$DZ,VLOOKUP($B$2,Summary!$V$4:$AA$15,F$1,0),0) -> 42705.38 | G19: =VLOOKUP($A:$A,Data_sheet_PTD!$M:$DZ,VLOOKUP($B$2,Summary!$V$4:$AA$15,G$1,0),0) -> 54730.24 | H19: =VLOOKUP($A:$A,Data_sheet_PTD!$M:$DZ,VLOOKUP($B$2,Summary!$V$4:$AA$15,H$1,0),0) -> 50204.67 | I19: =H19-G19 -> -4525.57 | J19: =VLOOKUP($A:$A,Data_sheet_PTD!$M:$DZ,VLOOKUP($B$2,Summary!$V$4:$AA$15,J$1,0),0) -> -4525.57 | K19: =VLOOKUP($A:$A,Data_sheet_PTD!$M:$DZ,VLOOKUP($B$2,Summary!$V$4:$AA$15,K$1,0),0) -> 0 | L19: =VLOOKUP($A:$A,Data_sheet_YTD!$M:$DZ,VLOOKUP($B$2,Summary!$V$4:$AA$15,L$1,0),0) -> 747616.95 | M19: =VLOOKUP($A:$A,Data_sheet_YTD!$M:$DZ,VLOOKUP($B$2,Summary!$V$4:$AA$15,M$1,0),0) -> 896840.57 | N19: =VLOOKUP($A:$A,Data_sheet_YTD!$M:$DZ,VLOOKUP($B$2,Summary!$V$4:$AA$15,N$1,0),0) -> 871512.9 | O19: =N19-M19 -> -25327.67 | P19: =VLOOKUP($A:$A,Data_sheet_YTD!$M:$DZ,VLOOKUP($B$2,Summary!$V$4:$AA$15,P$1,0),0) -> -42731.882 | Q19: =VLOOKUP($A:$A,Data_sheet_YTD!$M:$DZ,VLOOKUP($B$2,Summary!$V$4:$AA$15,Q$1,0),0) -> 17404.212 | R19: -1062.49 | S19: =R19-I19 -> 3463.08 | T19: =O19-P19-Q19 -> 1.1277734e-10
A20: CA111 | B20: =IF(F20>0,"O","X") -> O | C20: =IF(G20>0,"O","X") -> O | D20: =IF(H20>0,"O","X") -> O | E20: OPEN | F20: =VLOOKUP($A:$A,Data_sheet_PTD!$M:$DZ,VLOOKUP($B$2,Summary!$V$4:$AA$15,F$1,0),0) -> 62737.27 | G20: =VLOOKUP($A:$A,Data_sheet_PTD!$M:$DZ,VLOOKUP($B$2,Summary!$V$4:$AA$15,G$1,0),0) -> 78647.52 | H20: =VLOOKUP($A:$A,Data_sheet_PTD!$M:$DZ,VLOOKUP($B$2,Summary!$V$4:$AA$15,H$1,0),0) -> 74374.89 | I20: =H20-G20 -> -4272.63 | J20: =VLOOKUP($A:$A,Data_sheet_PTD!$M:$DZ,VLOOKUP($B$2,Summary!$V$4:$AA$15,J$1,0),0) -> -4272.63 | K20: =VLOOKUP($A:$A,Data_sheet_PTD!$M:$DZ,VLOOKUP($B$2,Summary!$V$4:$AA$15,K$1,0),0) -> 0 | L20: =VLOOKUP($A:$A,Data_sheet_YTD!$M:$DZ,VLOOKUP($B$2,Summary!$V$4:$AA$15,L$1,0),0) -> 1102837.7 | M20: =VLOOKUP($A:$A,Data_sheet_YTD!$M:$DZ,VLOOKUP($B$2,Summary!$V$4:$AA$15,M$1,0),0) -> 1282372.8 | N20: =VLOOKUP($A:$A,Data_sheet_YTD!$M:$DZ,VLOOKUP($B$2,Summary!$V$4:$AA$15,N$1,0),0) -> 1302493.4 | O20: =N20-M20 -> 20120.63 | P20: =VLOOKUP($A:$A,Data_sheet_YTD!$M:$DZ,VLOOKUP($B$2,Summary!$V$4:$AA$15,P$1,0),0) -> 7382.3307 | Q20: =VLOOKUP($A:$A,Data_sheet_YTD!$M:$DZ,VLOOKUP($B$2,Summary!$V$4:$AA$15,Q$1,0),0) -> 12738.299 | R20: 16056.8 | S20: =R20-I20 -> 20329.43 | T20: =O20-P20-Q20 -> -1.2732926e-10
A21: CA112 | B21: =IF(F21>0,"O","X") -> O | C21: =IF(G21>0,"O","X") -> O | D21: =IF(H21>0,"O","X") -> O | E21: OPEN | F21: =VLOOKUP($A:$A,Data_sheet_PTD!$M:$DZ,VLOOKUP($B$2,Summary!$V$4:$AA$15,F$1,0),0) -> 41724.1 | G21: =VLOOKUP($A:$A,Data_sheet_PTD!$M:$DZ,VLOOKUP($B$2,Summary!$V$4:$AA$15,G$1,0),0) -> 48982.46 | H21: =VLOOKUP($A:$A,Data_sheet_PTD!$M:$DZ,VLOOKUP($B$2,Summary!$V$4:$AA$15,H$1,0),0) -> 47464.29 | I21: =H21-G21 -> -1518.17 | J21: =VLOOKUP($A:$A,Data_sheet_PTD!$M:$DZ,VLOOKUP($B$2,Summary!$V$4:$AA$15,J$1,0),0) -> -1518.17 | K21: =VLOOKUP($A:$A,Data_sheet_PTD!$M:$DZ,VLOOKUP($B$2,Summary!$V$4:$AA$15,K$1,0),0) -> 0 | L21: =VLOOKUP($A:$A,Data_sheet_YTD!$M:$DZ,VLOOKUP($B$2,Summary!$V$4:$AA$15,L$1,0),0) -> 688138.94 | M21: =VLOOKUP($A:$A,Data_sheet_YTD!$M:$DZ,VLOOKUP($B$2,Summary!$V$4:$AA$15,M$1,0),0) -> 850227.01 | N21: =VLOOKUP($A:$A,Data_sheet_YTD!$M:$DZ,VLOOKUP($B$2,Summary!$V$4:$AA$15,N$1,0),0) -> 843610.96 | O21: =N21-M21 -> -6616.05 | P21: =VLOOKUP($A:$A,Data_sheet_YTD!$M:$DZ,VLOOKUP($B$2,Summary!$V$4:$AA$15,P$1,0),0) -> -10103.183 | Q21: =VLOOKUP($A:$A,Data_sheet_YTD!$M:$DZ,VLOOKUP($B$2,Summary!$V$4:$AA$15,Q$1,0),0) -> 3487.1327 | R21: 7020.95 | S21: =R21-I21 -> 8539.12 | T21: =O21-P21-Q21 -> 1.036824e-10
A22: CA114 | B22: =IF(F22>0,"O","X") -> X | C22: =IF(G22>0,"O","X") -> X | D22: =IF(H22>0,"O","X") -> X | E22: CLOSED | F22: =VLOOKUP($A:$A,Data_sheet_PTD!$M:$DZ,VLOOKUP($B$2,Summary!$V$4:$AA$15,F$1,0),0) -> 0 | G22: =VLOOKUP($A:$A,Data_sheet_PTD!$M:$DZ,VLOOKUP($B$2,Summary!$V$4:$AA$15,G$1,0),0) -> 0 | H22: =VLOOKUP($A:$A,Data_sheet_PTD!$M:$DZ,VLOOKUP($B$2,Summary!$V$4:$AA$15,H$1,0),0) -> 0 | I22: =H22-G22 -> 0 | J22: =VLOOKUP($A:$A,Data_sheet_PTD!$M:$DZ,VLOOKUP($B$2,Summary!$V$4:$AA$15,J$1,0),0) -> 0 | K22: =VLOOKUP($A:$A,Data_sheet_PTD!$M:$DZ,VLOOKUP($B$2,Summary!$V$4:$AA$15,K$1,0),0) -> 0 | L22: =VLOOKUP($A:$A,Data_sheet_YTD!$M:$DZ,VLOOKUP($B$2,Summary!$V$4:$AA$15,L$1,0),0) -> 0 | M22: =VLOOKUP($A:$A,Data_sheet_YTD!$M:$DZ,VLOOKUP($B$2,Summary!$V$4:$AA$15,M$1,0),0) -> 0 | N22: =VLOOKUP($A:$A,Data_sheet_YTD!$M:$DZ,VLOOKUP($B$2,Summary!$V$4:$AA$15,N$1,0),0) -> 0 | O22: =N22-M22 -> 0 | P22: =VLOOKUP($A:$A,Data_sheet_YTD!$M:$DZ,VLOOKUP($B$2,Summary!$V$4:$AA$15,P$1,0),0) -> 0 | Q22: =VLOOKUP($A:$A,Data_sheet_YTD!$M:$DZ,VLOOKUP($B$2,Summary!$V$4:$AA$15,Q$1,0),0) -> 0 | R22: 0 | S22: =R22-I22 -> 0 | T22: =O22-P22-Q22 -> 0 | V22: January | W22: N
A23: CA115 | B23: =IF(F23>0,"O","X") -> O | C23: =IF(G23>0,"O","X") -> O | D23: =IF(H23>0,"O","X") -> O | E23: OPEN | F23: =VLOOKUP($A:$A,Data_sheet_PTD!$M:$DZ,VLOOKUP($B$2,Summary!$V$4:$AA$15,F$1,0),0) -> 66160.09 | G23: =VLOOKUP($A:$A,Data_sheet_PTD!$M:$DZ,VLOOKUP($B$2,Summary!$V$4:$AA$15,G$1,0),0) -> 81001.76 | H23: =VLOOKUP($A:$A,Data_sheet_PTD!$M:$DZ,VLOOKUP($B$2,Summary!$V$4:$AA$15,H$1,0),0) -> 97740.81 | I23: =H23-G23 -> 16739.05 | J23: =VLOOKUP($A:$A,Data_sheet_PTD!$M:$DZ,VLOOKUP($B$2,Summary!$V$4:$AA$15,J$1,0),0) -> 16739.05 | K23: =VLOOKUP($A:$A,Data_sheet_PTD!$M:$DZ,VLOOKUP($B$2,Summary!$V$4:$AA$15,K$1,0),0) -> 0 | L23: =VLOOKUP($A:$A,Data_sheet_YTD!$M:$DZ,VLOOKUP($B$2,Summary!$V$4:$AA$15,L$1,0),0) -> 1106725.1 | M23: =VLOOKUP($A:$A,Data_sheet_YTD!$M:$DZ,VLOOKUP($B$2,Summary!$V$4:$AA$15,M$1,0),0) -> 1407457 | N23: =VLOOKUP($A:$A,Data_sheet_YTD!$M:$DZ,VLOOKUP($B$2,Summary!$V$4:$AA$15,N$1,0),0) -> 1678252.2 | O23: =N23-M23 -> 270795.12 | P23: =VLOOKUP($A:$A,Data_sheet_YTD!$M:$DZ,VLOOKUP($B$2,Summary!$V$4:$AA$15,P$1,0),0) -> 176436.23 | Q23: =VLOOKUP($A:$A,Data_sheet_YTD!$M:$DZ,VLOOKUP($B$2,Summary!$V$4:$AA$15,Q$1,0),0) -> 94358.886 | R23: 40146.4 | S23: =R23-I23 -> 23407.35 | T23: =O23-P23-Q23 -> 0 | V23: February | W23: O
A24: CA116 | B24: =IF(F24>0,"O","X") -> X | C24: =IF(G24>0,"O","X") -> X | D24: =IF(H24>0,"O","X") -> X | E24: CLOSED | F24: =VLOOKUP($A:$A,Data_sheet_PTD!$M:$DZ,VLOOKUP($B$2,Summary!$V$4:$AA$15,F$1,0),0) -> 0 | G24: =VLOOKUP($A:$A,Data_sheet_PTD!$M:$DZ,VLOOKUP($B$2,Summary!$V$4:$AA$15,G$1,0),0) -> 0 | H24: =VLOOKUP($A:$A,Data_sheet_PTD!$M:$DZ,VLOOKUP($B$2,Summary!$V$4:$AA$15,H$1,0),0) -> 0 | I24: =H24-G24 -> 0 | J24: =VLOOKUP($A:$A,Data_sheet_PTD!$M:$DZ,VLOOKUP($B$2,Summary!$V$4:$AA$15,J$1,0),0) -> 0 | K24: =VLOOKUP($A:$A,Data_sheet_PTD!$M:$DZ,VLOOKUP($B$2,Summary!$V$4:$AA$15,K$1,0),0) -> 0 | L24: =VLOOKUP($A:$A,Data_sheet_YTD!$M:$DZ,VLOOKUP($B$2,Summary!$V$4:$AA$15,L$1,0),0) -> 91114.25 | M24: =VLOOKUP($A:$A,Data_sheet_YTD!$M:$DZ,VLOOKUP($B$2,Summary!$V$4:$AA$15,M$1,0),0) -> 0 | N24: =VLOOKUP($A:$A,Data_sheet_YTD!$M:$DZ,VLOOKUP($B$2,Summary!$V$4:$AA$15,N$1,0),0) -> 0 | O24: =N24-M24 -> 0 | P24: =VLOOKUP($A:$A,Data_sheet_YTD!$M:$DZ,VLOOKUP($B$2,Summary!$V$4:$AA$15,P$1,0),0) -> 0 | Q24: =VLOOKUP($A:$A,Data_sheet_YTD!$M:$DZ,VLOOKUP($B$2,Summary!$V$4:$AA$15,Q$1,0),0) -> 0 | R24: 0 | S24: =R24-I24 -> 0 | T24: =O24-P24-Q24 -> 0 | V24: March | W24: P
A25: CA117 | B25: =IF(F25>0,"O","X") -> O | C25: =IF(G25>0,"O","X") -> O | D25: =IF(H25>0,"O","X") -> O | E25: OPEN | F25: =VLOOKUP($A:$A,Data_sheet_PTD!$M:$DZ,VLOOKUP($B$2,Summary!$V$4:$AA$15,F$1,0),0) -> 34959.31 | G25: =VLOOKUP($A:$A,Data_sheet_PTD!$M:$DZ,VLOOKUP($B$2,Summary!$V$4:$AA$15,G$1,0),0) -> 47781.21 | H25: =VLOOKUP($A:$A,Data_sheet_PTD!$M:$DZ,VLOOKUP($B$2,Summary!$V$4:$AA$15,H$1,0),0) -> 51789.54 | I25: =H25-G25 -> 4008.33 | J25: =VLOOKUP($A:$A,Data_sheet_PTD!$M:$DZ,VLOOKUP($B$2,Summary!$V$4:$AA$15,J$1,0),0) -> 4008.33 | K25: =VLOOKUP($A:$A,Data_sheet_PTD!$M:$DZ,VLOOKUP($B$2,Summary!$V$4:$AA$15,K$1,0),0) -> 0 | L25: =VLOOKUP($A:$A,Data_sheet_YTD!$M:$DZ,VLOOKUP($B$2,Summary!$V$4:$AA$15,L$1,0),0) -> 571274.32 | M25: =VLOOKUP($A:$A,Data_sheet_YTD!$M:$DZ,VLOOKUP($B$2,Summary!$V$4:$AA$15,M$1,0),0) -> 759758.99 | N25: =VLOOKUP($A:$A,Data_sheet_YTD!$M:$DZ,VLOOKUP($B$2,Summary!$V$4:$AA$15,N$1,0),0) -> 798694.08 | O25: =N25-M25 -> 38935.09 | P25: =VLOOKUP($A:$A,Data_sheet_YTD!$M:$DZ,VLOOKUP($B$2,Summary!$V$4:$AA$15,P$1,0),0) -> 21950.325 | Q25: =VLOOKUP($A:$A,Data_sheet_YTD!$M:$DZ,VLOOKUP($B$2,Summary!$V$4:$AA$15,Q$1,0),0) -> 16984.765 | R25: 4785.21 | S25: =R25-I25 -> 776.88 | T25: =O25-P25-Q25 -> 6.9121597e-11 | V25: April | W25: Q
A26: CA118 | B26: =IF(F26>0,"O","X") -> O | C26: =IF(G26>0,"O","X") -> O | D26: =IF(H26>0,"O","X") -> O | E26: OPEN | F26: =VLOOKUP($A:$A,Data_sheet_PTD!$M:$DZ,VLOOKUP($B$2,Summary!$V$4:$AA$15,F$1,0),0) -> 44438.55 | G26: =VLOOKUP($A:$A,Data_sheet_PTD!$M:$DZ,VLOOKUP($B$2,Summary!$V$4:$AA$15,G$1,0),0) -> 62318.78 | H26: =VLOOKUP($A:$A,Data_sheet_PTD!$M:$DZ,VLOOKUP($B$2,Summary!$V$4:$AA$15,H$1,0),0) -> 59644.47 | I26: =H26-G26 -> -2674.31 | J26: =VLOOKUP($A:$A,Data_sheet_PTD!$M:$DZ,VLOOKUP($B$2,Summary!$V$4:$AA$15,J$1,0),0) -> -7204.2697 | K26: =VLOOKUP($A:$A,Data_sheet_PTD!$M:$DZ,VLOOKUP($B$2,Summary!$V$4:$AA$15,K$1,0),0) -> 4529.9597 | L26: =VLOOKUP($A:$A,Data_sheet_YTD!$M:$DZ,VLOOKUP($B$2,Summary!$V$4:$AA$15,L$1,0),0) -> 711897 | M26: =VLOOKUP($A:$A,Data_sheet_YTD!$M:$DZ,VLOOKUP($B$2,Summary!$V$4:$AA$15,M$1,0),0) -> 926818.05 | N26: =VLOOKUP($A:$A,Data_sheet_YTD!$M:$DZ,VLOOKUP($B$2,Summary!$V$4:$AA$15,N$1,0),0) -> 971320.52 | O26: =N26-M26 -> 44502.47 | P26: =VLOOKUP($A:$A,Data_sheet_YTD!$M:$DZ,VLOOKUP($B$2,Summary!$V$4:$AA$15,P$1,0),0) -> -8127.1363 | Q26: =VLOOKUP($A:$A,Data_sheet_YTD!$M:$DZ,VLOOKUP($B$2,Summary!$V$4:$AA$15,Q$1,0),0) -> 52629.606 | R26: 10371.71 | S26: =R26-I26 -> 13046.02 | T26: =O26-P26-Q26 -> 0 | V26: May | W26: R
A27: CA119 | B27: =IF(F27>0,"O","X") -> O | C27: =IF(G27>0,"O","X") -> O | D27: =IF(H27>0,"O","X") -> O | E27: OPEN | F27: =VLOOKUP($A:$A,Data_sheet_PTD!$M:$DZ,VLOOKUP($B$2,Summary!$V$4:$AA$15,F$1,0),0) -> 42287.01 | G27: =VLOOKUP($A:$A,Data_sheet_PTD!$M:$DZ,VLOOKUP($B$2,Summary!$V$4:$AA$15,G$1,0),0) -> 49963.71 | H27: =VLOOKUP($A:$A,Data_sheet_PTD!$M:$DZ,VLOOKUP($B$2,Summary!$V$4:$AA$15,H$1,0),0) -> 52629.93 | I27: =H27-G27 -> 2666.22 | J27: =VLOOKUP($A:$A,Data_sheet_PTD!$M:$DZ,VLOOKUP($B$2,Summary!$V$4:$AA$15,J$1,0),0) -> 2666.22 | K27: =VLOOKUP($A:$A,Data_sheet_PTD!$M:$DZ,VLOOKUP($B$2,Summary!$V$4:$AA$15,K$1,0),0) -> 0 | L27: =VLOOKUP($A:$A,Data_sheet_YTD!$M:$DZ,VLOOKUP($B$2,Summary!$V$4:$AA$15,L$1,0),0) -> 778399.69 | M27: =VLOOKUP($A:$A,Data_sheet_YTD!$M:$DZ,VLOOKUP($B$2,Summary!$V$4:$AA$15,M$1,0),0) -> 890108.83 | N27: =VLOOKUP($A:$A,Data_sheet_YTD!$M:$DZ,VLOOKUP($B$2,Summary!$V$4:$AA$15,N$1,0),0) -> 910653.67 | O27: =N27-M27 -> 20544.84 | P27: =VLOOKUP($A:$A,Data_sheet_YTD!$M:$DZ,VLOOKUP($B$2,Summary!$V$4:$AA$15,P$1,0),0) -> 13652.671 | Q27: =VLOOKUP($A:$A,Data_sheet_YTD!$M:$DZ,VLOOKUP($B$2,Summary!$V$4:$AA$15,Q$1,0),0) -> 6892.1694 | R27: 8957.6 | S27: =R27-I27 -> 6291.38 | T27: =O27-P27-Q27 -> -4.0017767e-11 | V27: June | W27: S
A28: CA120 | B28: =IF(F28>0,"O","X") -> O | C28: =IF(G28>0,"O","X") -> O | D28: =IF(H28>0,"O","X") -> O | E28: OPEN | F28: =VLOOKUP($A:$A,Data_sheet_PTD!$M:$DZ,VLOOKUP($B$2,Summary!$V$4:$AA$15,F$1,0),0) -> 39112.73 | G28: =VLOOKUP($A:$A,Data_sheet_PTD!$M:$DZ,VLOOKUP($B$2,Summary!$V$4:$AA$15,G$1,0),0) -> 46863.45 | H28: =VLOOKUP($A:$A,Data_sheet_PTD!$M:$DZ,VLOOKUP($B$2,Summary!$V$4:$AA$15,H$1,0),0) -> 51502.9 | I28: =H28-G28 -> 4639.45 | J28: =VLOOKUP($A:$A,Data_sheet_PTD!$M:$DZ,VLOOKUP($B$2,Summary!$V$4:$AA$15,J$1,0),0) -> 463.53919 | K28: =VLOOKUP($A:$A,Data_sheet_PTD!$M:$DZ,VLOOKUP($B$2,Summary!$V$4:$AA$15,K$1,0),0) -> 4175.9108 | L28: =VLOOKUP($A:$A,Data_sheet_YTD!$M:$DZ,VLOOKUP($B$2,Summary!$V$4:$AA$15,L$1,0),0) -> 668799.8 | M28: =VLOOKUP($A:$A,Data_sheet_YTD!$M:$DZ,VLOOKUP($B$2,Summary!$V$4:$AA$15,M$1,0),0) -> 822136.26 | N28: =VLOOKUP($A:$A,Data_sheet_YTD!$M:$DZ,VLOOKUP($B$2,Summary!$V$4:$AA$15,N$1,0),0) -> 850178.41 | O28: =N28-M28 -> 28042.15 | P28: =VLOOKUP($A:$A,Data_sheet_YTD!$M:$DZ,VLOOKUP($B$2,Summary!$V$4:$AA$15,P$1,0),0) -> -21244.344 | Q28: =VLOOKUP($A:$A,Data_sheet_YTD!$M:$DZ,VLOOKUP($B$2,Summary!$V$4:$AA$15,Q$1,0),0) -> 49286.494 | R28: 8459.08 | S28: =R28-I28 -> 3819.63 | T28: =O28-P28-Q28 -> 2.0372681e-10 | V28: July | W28: T
A29: CA121 | B29: =IF(F29>0,"O","X") -> X | C29: =IF(G29>0,"O","X") -> X | D29: =IF(H29>0,"O","X") -> X | E29: CLOSED | F29: =VLOOKUP($A:$A,Data_sheet_PTD!$M:$DZ,VLOOKUP($B$2,Summary!$V$4:$AA$15,F$1,0),0) -> 0 | G29: =VLOOKUP($A:$A,Data_sheet_PTD!$M:$DZ,VLOOKUP($B$2,Summary!$V$4:$AA$15,G$1,0),0) -> 0 | H29: =VLOOKUP($A:$A,Data_sheet_PTD!$M:$DZ,VLOOKUP($B$2,Summary!$V$4:$AA$15,H$1,0),0) -> 0 | I29: =H29-G29 -> 0 | J29: =VLOOKUP($A:$A,Data_sheet_PTD!$M:$DZ,VLOOKUP($B$2,Summary!$V$4:$AA$15,J$1,0),0) -> 0 | K29: =VLOOKUP($A:$A,Data_sheet_PTD!$M:$DZ,VLOOKUP($B$2,Summary!$V$4:$AA$15,K$1,0),0) -> 0 | L29: =VLOOKUP($A:$A,Data_sheet_YTD!$M:$DZ,VLOOKUP($B$2,Summary!$V$4:$AA$15,L$1,0),0) -> 0 | M29: =VLOOKUP($A:$A,Data_sheet_YTD!$M:$DZ,VLOOKUP($B$2,Summary!$V$4:$AA$15,M$1,0),0) -> 0 | N29: =VLOOKUP($A:$A,Data_sheet_YTD!$M:$DZ,VLOOKUP($B$2,Summary!$V$4:$AA$15,N$1,0),0) -> 0 | O29: =N29-M29 -> 0 | P29: =VLOOKUP($A:$A,Data_sheet_YTD!$M:$DZ,VLOOKUP($B$2,Summary!$V$4:$AA$15,P$1,0),0) -> 0 | Q29: =VLOOKUP($A:$A,Data_sheet_YTD!$M:$DZ,VLOOKUP($B$2,Summary!$V$4:$AA$15,Q$1,0),0) -> 0 | R29: 0 | S29: =R29-I29 -> 0 | T29: =O29-P29-Q29 -> 0 | V29: August | W29: U
A30: CA123 | B30: =IF(F30>0,"O","X") -> O | C30: =IF(G30>0,"O","X") -> O | D30: =IF(H30>0,"O","X") -> O | E30: OPEN | F30: =VLOOKUP($A:$A,Data_sheet_PTD!$M:$DZ,VLOOKUP($B$2,Summary!$V$4:$AA$15,F$1,0),0) -> 45063 | G30: =VLOOKUP($A:$A,Data_sheet_PTD!$M:$DZ,VLOOKUP($B$2,Summary!$V$4:$AA$15,G$1,0),0) -> 58703.52 | H30: =VLOOKUP($A:$A,Data_sheet_PTD!$M:$DZ,VLOOKUP($B$2,Summary!$V$4:$AA$15,H$1,0),0) -> 59865.35 | I30: =H30-G30 -> 1161.83 | J30: =VLOOKUP($A:$A,Data_sheet_PTD!$M:$DZ,VLOOKUP($B$2,Summary!$V$4:$AA$15,J$1,0),0) -> 1161.83 | K30: =VLOOKUP($A:$A,Data_sheet_PTD!$M:$DZ,VLOOKUP($B$2,Summary!$V$4:$AA$15,K$1,0),0) -> 0 | L30: =VLOOKUP($A:$A,Data_sheet_YTD!$M:$DZ,VLOOKUP($B$2,Summary!$V$4:$AA$15,L$1,0),0) -> 779991.78 | M30: =VLOOKUP($A:$A,Data_sheet_YTD!$M:$DZ,VLOOKUP($B$2,Summary!$V$4:$AA$15,M$1,0),0) -> 1025593.6 | N30: =VLOOKUP($A:$A,Data_sheet_YTD!$M:$DZ,VLOOKUP($B$2,Summary!$V$4:$AA$15,N$1,0),0) -> 1055346.4 | O30: =N30-M30 -> 29752.83 | P30: =VLOOKUP($A:$A,Data_sheet_YTD!$M:$DZ,VLOOKUP($B$2,Summary!$V$4:$AA$15,P$1,0),0) -> -1431.4627 | Q30: =VLOOKUP($A:$A,Data_sheet_YTD!$M:$DZ,VLOOKUP($B$2,Summary!$V$4:$AA$15,Q$1,0),0) -> 31184.293 | R30: 2633.38 | S30: =R30-I30 -> 1471.55 | T30: =O30-P30-Q30 -> -1.6734703e-10 | V30: September | W30: V
A31: CA125 | B31: =IF(F31>0,"O","X") -> O | C31: =IF(G31>0,"O","X") -> O | D31: =IF(H31>0,"O","X") -> O | E31: OPEN | F31: =VLOOKUP($A:$A,Data_sheet_PTD!$M:$DZ,VLOOKUP($B$2,Summary!$V$4:$AA$15,F$1,0),0) -> 54195.61 | G31: =VLOOKUP($A:$A,Data_sheet_PTD!$M:$DZ,VLOOKUP($B$2,Summary!$V$4:$AA$15,G$1,0),0) -> 63894.58 | H31: =VLOOKUP($A:$A,Data_sheet_PTD!$M:$DZ,VLOOKUP($B$2,Summary!$V$4:$AA$15,H$1,0),0) -> 61101.18 | I31: =H31-G31 -> -2793.4 | J31: =VLOOKUP($A:$A,Data_sheet_PTD!$M:$DZ,VLOOKUP($B$2,Summary!$V$4:$AA$15,J$1,0),0) -> -2793.4 | K31: =VLOOKUP($A:$A,Data_sheet_PTD!$M:$DZ,VLOOKUP($B$2,Summary!$V$4:$AA$15,K$1,0),0) -> 0 | L31: =VLOOKUP($A:$A,Data_sheet_YTD!$M:$DZ,VLOOKUP($B$2,Summary!$V$4:$AA$15,L$1,0),0) -> 928767.92 | M31: =VLOOKUP($A:$A,Data_sheet_YTD!$M:$DZ,VLOOKUP($B$2,Summary!$V$4:$AA$15,M$1,0),0) -> 1202661.1 | N31: =VLOOKUP($A:$A,Data_sheet_YTD!$M:$DZ,VLOOKUP($B$2,Summary!$V$4:$AA$15,N$1,0),0) -> 1277852.2 | O31: =N31-M31 -> 75191.04 | P31: =VLOOKUP($A:$A,Data_sheet_YTD!$M:$DZ,VLOOKUP($B$2,Summary!$V$4:$AA$15,P$1,0),0) -> 75191.04 | Q31: =VLOOKUP($A:$A,Data_sheet_YTD!$M:$DZ,VLOOKUP($B$2,Summary!$V$4:$AA$15,Q$1,0),0) -> 0 | R31: 16537.93 | S31: =R31-I31 -> 19331.33 | T31: =O31-P31-Q31 -> 7.2759576e-11 | V31: October | W31: W
A32: CA126 | B32: =IF(F32>0,"O","X") -> X | C32: =IF(G32>0,"O","X") -> X | D32: =IF(H32>0,"O","X") -> X | E32: CLOSED | F32: =VLOOKUP($A:$A,Data_sheet_PTD!$M:$DZ,VLOOKUP($B$2,Summary!$V$4:$AA$15,F$1,0),0) -> 0 | G32: =VLOOKUP($A:$A,Data_sheet_PTD!$M:$DZ,VLOOKUP($B$2,Summary!$V$4:$AA$15,G$1,0),0) -> 0 | H32: =VLOOKUP($A:$A,Data_sheet_PTD!$M:$DZ,VLOOKUP($B$2,Summary!$V$4:$AA$15,H$1,0),0) -> 0 | I32: =H32-G32 -> 0 | J32: =VLOOKUP($A:$A,Data_sheet_PTD!$M:$DZ,VLOOKUP($B$2,Summary!$V$4:$AA$15,J$1,0),0) -> 0 | K32: =VLOOKUP($A:$A,Data_sheet_PTD!$M:$DZ,VLOOKUP($B$2,Summary!$V$4:$AA$15,K$1,0),0) -> 0 | L32: =VLOOKUP($A:$A,Data_sheet_YTD!$M:$DZ,VLOOKUP($B$2,Summary!$V$4:$AA$15,L$1,0),0) -> 0 | M32: =VLOOKUP($A:$A,Data_sheet_YTD!$M:$DZ,VLOOKUP($B$2,Summary!$V$4:$AA$15,M$1,0),0) -> 0 | N32: =VLOOKUP($A:$A,Data_sheet_YTD!$M:$DZ,VLOOKUP($B$2,Summary!$V$4:$AA$15,N$1,0),0) -> 0 | O32: =N32-M32 -> 0 | P32: =VLOOKUP($A:$A,Data_sheet_YTD!$M:$DZ,VLOOKUP($B$2,Summary!$V$4:$AA$15,P$1,0),0) -> 0 | Q32: =VLOOKUP($A:$A,Data_sheet_YTD!$M:$DZ,VLOOKUP($B$2,Summary!$V$4:$AA$15,Q$1,0),0) -> 0 | R32: 0 | S32: =R32-I32 -> 0 | T32: =O32-P32-Q32 -> 0 | V32: November | W32: X
A33: CA128 | B33: =IF(F33>0,"O","X") -> O | C33: =IF(G33>0,"O","X") -> O | D33: =IF(H33>0,"O","X") -> O | E33: OPEN | F33: =VLOOKUP($A:$A,Data_sheet_PTD!$M:$DZ,VLOOKUP($B$2,Summary!$V$4:$AA$15,F$1,0),0) -> 27054.94 | G33: =VLOOKUP($A:$A,Data_sheet_PTD!$M:$DZ,VLOOKUP($B$2,Summary!$V$4:$AA$15,G$1,0),0) -> 38750.23 | H33: =VLOOKUP($A:$A,Data_sheet_PTD!$M:$DZ,VLOOKUP($B$2,Summary!$V$4:$AA$15,H$1,0),0) -> 44631.06 | I33: =H33-G33 -> 5880.83 | J33: =VLOOKUP($A:$A,Data_sheet_PTD!$M:$DZ,VLOOKUP($B$2,Summary!$V$4:$AA$15,J$1,0),0) -> 2944.5761 | K33: =VLOOKUP($A:$A,Data_sheet_PTD!$M:$DZ,VLOOKUP($B$2,Summary!$V$4:$AA$15,K$1,0),0) -> 2936.2539 | L33: =VLOOKUP($A:$A,Data_sheet_YTD!$M:$DZ,VLOOKUP($B$2,Summary!$V$4:$AA$15,L$1,0),0) -> 651011.89 | M33: =VLOOKUP($A:$A,Data_sheet_YTD!$M:$DZ,VLOOKUP($B$2,Summary!$V$4:$AA$15,M$1,0),0) -> 713392.58 | N33: =VLOOKUP($A:$A,Data_sheet_YTD!$M:$DZ,VLOOKUP($B$2,Summary!$V$4:$AA$15,N$1,0),0) -> 698371.76 | O33: =N33-M33 -> -15020.82 | P33: =VLOOKUP($A:$A,Data_sheet_YTD!$M:$DZ,VLOOKUP($B$2,Summary!$V$4:$AA$15,P$1,0),0) -> -45773.98 | Q33: =VLOOKUP($A:$A,Data_sheet_YTD!$M:$DZ,VLOOKUP($B$2,Summary!$V$4:$AA$15,Q$1,0),0) -> 30753.16 | R33: 6345.58 | S33: =R33-I33 -> 464.75 | T33: =O33-P33-Q33 -> 6.9121597e-11 | V33: December | W33: Y
A34: CA129 | B34: =IF(F34>0,"O","X") -> O | C34: =IF(G34>0,"O","X") -> O | D34: =IF(H34>0,"O","X") -> O | E34: OPEN | F34: =VLOOKUP($A:$A,Data_sheet_PTD!$M:$DZ,VLOOKUP($B$2,Summary!$V$4:$AA$15,F$1,0),0) -> 49483.41 | G34: =VLOOKUP($A:$A,Data_sheet_PTD!$M:$DZ,VLOOKUP($B$2,Summary!$V$4:$AA$15,G$1,0),0) -> 63347.82 | H34: =VLOOKUP($A:$A,Data_sheet_PTD!$M:$DZ,VLOOKUP($B$2,Summary!$V$4:$AA$15,H$1,0),0) -> 65395.67 | I34: =H34-G34 -> 2047.85 | J34: =VLOOKUP($A:$A,Data_sheet_PTD!$M:$DZ,VLOOKUP($B$2,Summary!$V$4:$AA$15,J$1,0),0) -> 392.26342 | K34: =VLOOKUP($A:$A,Data_sheet_PTD!$M:$DZ,VLOOKUP($B$2,Summary!$V$4:$AA$15,K$1,0),0) -> 1655.5866 | L34: =VLOOKUP($A:$A,Data_sheet_YTD!$M:$DZ,VLOOKUP($B$2,Summary!$V$4:$AA$15,L$1,0),0) -> 915342.43 | M34: =VLOOKUP($A:$A,Data_sheet_YTD!$M:$DZ,VLOOKUP($B$2,Summary!$V$4:$AA$15,M$1,0),0) -> 1150445.6 | N34: =VLOOKUP($A:$A,Data_sheet_YTD!$M:$DZ,VLOOKUP($B$2,Summary!$V$4:$AA$15,N$1,0),0) -> 1272642.8 | O34: =N34-M34 -> 122197.23 | P34: =VLOOKUP($A:$A,Data_sheet_YTD!$M:$DZ,VLOOKUP($B$2,Summary!$V$4:$AA$15,P$1,0),0) -> 71105.217 | Q34: =VLOOKUP($A:$A,Data_sheet_YTD!$M:$DZ,VLOOKUP($B$2,Summary!$V$4:$AA$15,Q$1,0),0) -> 51092.013 | R34: 22311.83 | S34: =R34-I34 -> 20263.98 | T34: =O34-P34-Q34 -> -1.5279511e-10
A35: CA130 | B35: =IF(F35>0,"O","X") -> O | C35: =IF(G35>0,"O","X") -> O | D35: =IF(H35>0,"O","X") -> O | E35: OPEN | F35: =VLOOKUP($A:$A,Data_sheet_PTD!$M:$DZ,VLOOKUP($B$2,Summary!$V$4:$AA$15,F$1,0),0) -> 48442.95 | G35: =VLOOKUP($A:$A,Data_sheet_PTD!$M:$DZ,VLOOKUP($B$2,Summary!$V$4:$AA$15,G$1,0),0) -> 53547.46 | H35: =VLOOKUP($A:$A,Data_sheet_PTD!$M:$DZ,VLOOKUP($B$2,Summary!$V$4:$AA$15,H$1,0),0) -> 50116.63 | I35: =H35-G35 -> -3430.83 | J35: =VLOOKUP($A:$A,Data_sheet_PTD!$M:$DZ,VLOOKUP($B$2,Summary!$V$4:$AA$15,J$1,0),0) -> -4699.6054 | K35: =VLOOKUP($A:$A,Data_sheet_PTD!$M:$DZ,VLOOKUP($B$2,Summary!$V$4:$AA$15,K$1,0),0) -> 1268.7754 | L35: =VLOOKUP($A:$A,Data_sheet_YTD!$M:$DZ,VLOOKUP($B$2,Summary!$V$4:$AA$15,L$1,0),0) -> 845405.11 | M35: =VLOOKUP($A:$A,Data_sheet_YTD!$M:$DZ,VLOOKUP($B$2,Summary!$V$4:$AA$15,M$1,0),0) -> 965170.73 | N35: =VLOOKUP($A:$A,Data_sheet_YTD!$M:$DZ,VLOOKUP($B$2,Summary!$V$4:$AA$15,N$1,0),0) -> 949731.93 | O35: =N35-M35 -> -15438.8 | P35: =VLOOKUP($A:$A,Data_sheet_YTD!$M:$DZ,VLOOKUP($B$2,Summary!$V$4:$AA$15,P$1,0),0) -> -35947.825 | Q35: =VLOOKUP($A:$A,Data_sheet_YTD!$M:$DZ,VLOOKUP($B$2,Summary!$V$4:$AA$15,Q$1,0),0) -> 20509.025 | R35: 5590.11 | S35: =R35-I35 -> 9020.94 | T35: =O35-P35-Q35 -> 5.4569682e-11
A36: CA131 | B36: =IF(F36>0,"O","X") -> O | C36: =IF(G36>0,"O","X") -> O | D36: =IF(H36>0,"O","X") -> O | E36: OPEN | F36: =VLOOKUP($A:$A,Data_sheet_PTD!$M:$DZ,VLOOKUP($B$2,Summary!$V$4:$AA$15,F$1,0),0) -> 69993.14 | G36: =VLOOKUP($A:$A,Data_sheet_PTD!$M:$DZ,VLOOKUP($B$2,Summary!$V$4:$AA$15,G$1,0),0) -> 78078.28 | H36: =VLOOKUP($A:$A,Data_sheet_PTD!$M:$DZ,VLOOKUP($B$2,Summary!$V$4:$AA$15,H$1,0),0) -> 79547.91 | I36: =H36-G36 -> 1469.63 | J36: =VLOOKUP($A:$A,Data_sheet_PTD!$M:$DZ,VLOOKUP($B$2,Summary!$V$4:$AA$15,J$1,0),0) -> 1469.63 | K36: =VLOOKUP($A:$A,Data_sheet_PTD!$M:$DZ,VLOOKUP($B$2,Summary!$V$4:$AA$15,K$1,0),0) -> 0 | L36: =VLOOKUP($A:$A,Data_sheet_YTD!$M:$DZ,VLOOKUP($B$2,Summary!$V$4:$AA$15,L$1,0),0) -> 1142949.8 | M36: =VLOOKUP($A:$A,Data_sheet_YTD!$M:$DZ,VLOOKUP($B$2,Summary!$V$4:$AA$15,M$1,0),0) -> 1308772.3 | N36: =VLOOKUP($A:$A,Data_sheet_YTD!$M:$DZ,VLOOKUP($B$2,Summary!$V$4:$AA$15,N$1,0),0) -> 1298360.1 | O36: =N36-M36 -> -10412.24 | P36: =VLOOKUP($A:$A,Data_sheet_YTD!$M:$DZ,VLOOKUP($B$2,Summary!$V$4:$AA$15,P$1,0),0) -> -57560.271 | Q36: =VLOOKUP($A:$A,Data_sheet_YTD!$M:$DZ,VLOOKUP($B$2,Summary!$V$4:$AA$15,Q$1,0),0) -> 47148.031 | R36: -3394.13 | S36: =R36-I36 -> -4863.76 | T36: =O36-P36-Q36 -> -3.2741809e-10
A37: CA132 | B37: =IF(F37>0,"O","X") -> O | C37: =IF(G37>0,"O","X") -> O | D37: =IF(H37>0,"O","X") -> O | E37: OPEN | F37: =VLOOKUP($A:$A,Data_sheet_PTD!$M:$DZ,VLOOKUP($B$2,Summary!$V$4:$AA$15,F$1,0),0) -> 22364.55 | G37: =VLOOKUP($A:$A,Data_sheet_PTD!$M:$DZ,VLOOKUP($B$2,Summary!$V$4:$AA$15,G$1,0),0) -> 25628.82 | H37: =VLOOKUP($A:$A,Data_sheet_PTD!$M:$DZ,VLOOKUP($B$2,Summary!$V$4:$AA$15,H$1,0),0) -> 51471.17 | I37: =H37-G37 -> 25842.35 | J37: =VLOOKUP($A:$A,Data_sheet_PTD!$M:$DZ,VLOOKUP($B$2,Summary!$V$4:$AA$15,J$1,0),0) -> 28155.661 | K37: =VLOOKUP($A:$A,Data_sheet_PTD!$M:$DZ,VLOOKUP($B$2,Summary!$V$4:$AA$15,K$1,0),0) -> -2313.311 | L37: =VLOOKUP($A:$A,Data_sheet_YTD!$M:$DZ,VLOOKUP($B$2,Summary!$V$4:$AA$15,L$1,0),0) -> 466557.44 | M37: =VLOOKUP($A:$A,Data_sheet_YTD!$M:$DZ,VLOOKUP($B$2,Summary!$V$4:$AA$15,M$1,0),0) -> 553977.37 | N37: =VLOOKUP($A:$A,Data_sheet_YTD!$M:$DZ,VLOOKUP($B$2,Summary!$V$4:$AA$15,N$1,0),0) -> 809429.97 | O37: =N37-M37 -> 255452.6 | P37: =VLOOKUP($A:$A,Data_sheet_YTD!$M:$DZ,VLOOKUP($B$2,Summary!$V$4:$AA$15,P$1,0),0) -> 266127.87 | Q37: =VLOOKUP($A:$A,Data_sheet_YTD!$M:$DZ,VLOOKUP($B$2,Summary!$V$4:$AA$15,Q$1,0),0) -> -10675.268 | R37: 49303.85 | S37: =R37-I37 -> 23461.5 | T37: =O37-P37-Q37 -> 1.7280399e-10
A38: CA133 | B38: =IF(F38>0,"O","X") -> O | C38: =IF(G38>0,"O","X") -> O | D38: =IF(H38>0,"O","X") -> O | E38: OPEN | F38: =VLOOKUP($A:$A,Data_sheet_PTD!$M:$DZ,VLOOKUP($B$2,Summary!$V$4:$AA$15,F$1,0),0) -> 96821.11 | G38: =VLOOKUP($A:$A,Data_sheet_PTD!$M:$DZ,VLOOKUP($B$2,Summary!$V$4:$AA$15,G$1,0),0) -> 101498.43 | H38: =VLOOKUP($A:$A,Data_sheet_PTD!$M:$DZ,VLOOKUP($B$2,Summary!$V$4:$AA$15,H$1,0),0) -> 117350.61 | I38: =H38-G38 -> 15852.18 | J38: =VLOOKUP($A:$A,Data_sheet_PTD!$M:$DZ,VLOOKUP($B$2,Summary!$V$4:$AA$15,J$1,0),0) -> 15852.18 | K38: =VLOOKUP($A:$A,Data_sheet_PTD!$M:$DZ,VLOOKUP($B$2,Summary!$V$4:$AA$15,K$1,0),0) -> 0 | L38: =VLOOKUP($A:$A,Data_sheet_YTD!$M:$DZ,VLOOKUP($B$2,Summary!$V$4:$AA$15,L$1,0),0) -> 1478942.3 | M38: =VLOOKUP($A:$A,Data_sheet_YTD!$M:$DZ,VLOOKUP($B$2,Summary!$V$4:$AA$15,M$1,0),0) -> 1709611.3 | N38: =VLOOKUP($A:$A,Data_sheet_YTD!$M:$DZ,VLOOKUP($B$2,Summary!$V$4:$AA$15,N$1,0),0) -> 1759125.2 | O38: =N38-M38 -> 49513.86 | P38: =VLOOKUP($A:$A,Data_sheet_YTD!$M:$DZ,VLOOKUP($B$2,Summary!$V$4:$AA$15,P$1,0),0) -> 38784.954 | Q38: =VLOOKUP($A:$A,Data_sheet_YTD!$M:$DZ,VLOOKUP($B$2,Summary!$V$4:$AA$15,Q$1,0),0) -> 10728.906 | R38: 5444.91 | S38: =R38-I38 -> -10407.27 | T38: =O38-P38-Q38 -> 9.094947e-11
A39: CA134 | B39: =IF(F39>0,"O","X") -> X | C39: =IF(G39>0,"O","X") -> X | D39: =IF(H39>0,"O","X") -> X | E39: CLOSED | F39: =VLOOKUP($A:$A,Data_sheet_PTD!$M:$DZ,VLOOKUP($B$2,Summary!$V$4:$AA$15,F$1,0),0) -> 0 | G39: =VLOOKUP($A:$A,Data_sheet_PTD!$M:$DZ,VLOOKUP($B$2,Summary!$V$4:$AA$15,G$1,0),0) -> 0 | H39: =VLOOKUP($A:$A,Data_sheet_PTD!$M:$DZ,VLOOKUP($B$2,Summary!$V$4:$AA$15,H$1,0),0) -> 0 | I39: =H39-G39 -> 0 | J39: =VLOOKUP($A:$A,Data_sheet_PTD!$M:$DZ,VLOOKUP($B$2,Summary!$V$4:$AA$15,J$1,0),0) -> 0 | K39: =VLOOKUP($A:$A,Data_sheet_PTD!$M:$DZ,VLOOKUP($B$2,Summary!$V$4:$AA$15,K$1,0),0) -> 0 | L39: =VLOOKUP($A:$A,Data_sheet_YTD!$M:$DZ,VLOOKUP($B$2,Summary!$V$4:$AA$15,L$1,0),0) -> 0 | M39: =VLOOKUP($A:$A,Data_sheet_YTD!$M:$DZ,VLOOKUP($B$2,Summary!$V$4:$AA$15,M$1,0),0) -> 0 | N39: =VLOOKUP($A:$A,Data_sheet_YTD!$M:$DZ,VLOOKUP($B$2,Summary!$V$4:$AA$15,N$1,0),0) -> 0 | O39: =N39-M39 -> 0 | P39: =VLOOKUP($A:$A,Data_sheet_YTD!$M:$DZ,VLOOKUP($B$2,Summary!$V$4:$AA$15,P$1,0),0) -> 0 | Q39: =VLOOKUP($A:$A,Data_sheet_YTD!$M:$DZ,VLOOKUP($B$2,Summary!$V$4:$AA$15,Q$1,0),0) -> 0 | R39: 0 | S39: =R39-I39 -> 0 | T39: =O39-P39-Q39 -> 0
A40: CA136 | B40: =IF(F40>0,"O","X") -> O | C40: =IF(G40>0,"O","X") -> O | D40: =IF(H40>0,"O","X") -> O | E40: OPEN | F40: =VLOOKUP($A:$A,Data_sheet_PTD!$M:$DZ,VLOOKUP($B$2,Summary!$V$4:$AA$15,F$1,0),0) -> 51511.44 | G40: =VLOOKUP($A:$A,Data_sheet_PTD!$M:$DZ,VLOOKUP($B$2,Summary!$V$4:$AA$15,G$1,0),0) -> 65551.08 | H40: =VLOOKUP($A:$A,Data_sheet_PTD!$M:$DZ,VLOOKUP($B$2,Summary!$V$4:$AA$15,H$1,0),0) -> 60800.43 | I40: =H40-G40 -> -4750.65 | J40: =VLOOKUP($A:$A,Data_sheet_PTD!$M:$DZ,VLOOKUP($B$2,Summary!$V$4:$AA$15,J$1,0),0) -> -7680.7912 | K40: =VLOOKUP($A:$A,Data_sheet_PTD!$M:$DZ,VLOOKUP($B$2,Summary!$V$4:$AA$15,K$1,0),0) -> 2930.1412 | L40: =VLOOKUP($A:$A,Data_sheet_YTD!$M:$DZ,VLOOKUP($B$2,Summary!$V$4:$AA$15,L$1,0),0) -> 1049279.6 | M40: =VLOOKUP($A:$A,Data_sheet_YTD!$M:$DZ,VLOOKUP($B$2,Summary!$V$4:$AA$15,M$1,0),0) -> 1342496.8 | N40: =VLOOKUP($A:$A,Data_sheet_YTD!$M:$DZ,VLOOKUP($B$2,Summary!$V$4:$AA$15,N$1,0),0) -> 1378190.1 | O40: =N40-M40 -> 35693.33 | P40: =VLOOKUP($A:$A,Data_sheet_YTD!$M:$DZ,VLOOKUP($B$2,Summary!$V$4:$AA$15,P$1,0),0) -> -30636.225 | Q40: =VLOOKUP($A:$A,Data_sheet_YTD!$M:$DZ,VLOOKUP($B$2,Summary!$V$4:$AA$15,Q$1,0),0) -> 66329.555 | R40: 24926.91 | S40: =R40-I40 -> 29677.56 | T40: =O40-P40-Q40 -> 0
...

Sheet Playbook by FZ
B2: CA168
B3: SSS | C3: January | D3: February | E3: March | F3: April | G3: May | H3: June | I3: July | J3: August | K3: September | L3: October | M3: November | N3: December | O3: YTD
B4: Total
B5: Volume
B6: Price

Sheet Data_sheet_PTD
M1: 1 | N1: 2 | O1: 3 | P1: 4 | Q1: 5 | R1: 6 | S1: 7 | T1: 8 | U1: 9 | V1: 10 | W1: 11 | X1: 12 | Y1: 13 | Z1: 14 | AA1: 15 | AB1: 16 | AC1: 17 | AD1: 18 | AE1: 19 | AF1: 20 | AG1: 21 | AH1: 22 | AI1: 23 | AJ1: 24 | AK1: 25 | AL1: 26 | AM1: 27 | AN1: 28 | AO1: 29 | AP1: 30 | AQ1: 31 | AR1: 32 | AS1: 33 | AT1: 34 | AU1: 35 | AV1: 36 | AW1: 37 | AX1: 38 | AY1: 39 | AZ1: 40 | BA1: 41 | BB1: 42 | BC1: 43 | BD1: 44 | BE1: 45 | BF1: 46 | BG1: 47 | BH1: 48 | BI1: 49 | BJ1: 50 | BK1: 51 | BL1: 52 | BM1: 53 | BN1: 54 | BO1: 55 | BP1: 56 | BQ1: 57 | BR1: 58 | BS1: 59 | BT1: 60 | BU1: 61 | BV1: 62 | BW1: 63 | BX1: 64 | BY1: 65 | BZ1: 66 | CA1: 67 | CB1: 68 | CC1: 69 | CD1: 70 | CE1: 71 | CF1: 72 | CG1: 73 | CH1: 74 | CI1: 75 | CJ1: 76 | CK1: 77 | CL1: 78 | CM1: 79 | CN1: 80 | CO1: 81 | CP1: 82 | CQ1: 83 | CR1: 84 | CS1: 85 | CT1: 86 | CU1: 87 | CV1: 88 | CW1: 89 | CX1: 90 | CY1: 91 | CZ1: 92 | DA1: 93 | DB1: 94 | DC1: 95 | DD1: 96 | DE1: 97 | DF1: 98 | DG1: 99 | DH1: 100 | DI1: 101 | DJ1: 102 | DK1: 103 | DL1: 104 | DM1: 105 | DN1: 106 | DO1: 107 | DP1: 108 | DQ1: 109 | DR1: 110 | DS1: 111 | DT1: 112 | DU1: 113 | DV1: 114 | DW1: 115 | DX1: 116 | DY1: 117 | DZ1: 118
N2: 2022 | O2: 2022 | P2: 2022 | Q2: 2022 | R2: 2022 | S2: 2022 | T2: 2022 | U2: 2022 | V2: 2022 | W2: 2022 | X2: 2022 | Y2: 2022 | Z2: Manual | AA2: 2023 | AB2: 2023 | AC2: 2023 | AD2: 2023 | AE2: 2023 | AF2: 2023 | AG2: 2023 | AH2: 2023 | AI2: 2023 | AJ2: 2023 | AK2: 2023 | AL2: 2023 | AM2: Manual | AN2: 2024 | AO2: 2024 | AP2: 2024 | AQ2: 2024 | AR2: 2024 | AS2: 2024 | AT2: 2024 | AU2: 2024 | AV2: 2024 | AW2: 2024 | AX2: 2024 | AY2: 2024 | AZ2: Manual | BA2: 50 | BB2: 51 | BC2: 52 | BD2: 53 | BE2: 54 | BF2: 55 | BG2: 56 | BH2: 57 | BI2: 58 | BJ2: 59 | BK2: 60 | BL2: 61 | BM2: Manual | BN2: 62 | BO2: 63 | BP2: 64 | BQ2: 65 | BR2: 66 | BS2: 67 | BT2: 68 | BU2: 69 | BV2: 70 | BW2: 71 | BX2: 72 | BY2: 73 | BZ2: Manual | CA2: oz | CB2: oz | CC2: oz | CM2: Manual | CN2: oz | CO2: oz | CP2: oz | CZ2: Manual | DM2: Manual | DZ2: Manual
N3: January | O3: February | P3: March | Q3: April | R3: May | S3: June | T3: July | U3: August | V3: September | W3: October | X3: November | Y3: December | AA3: January | AB3: February | AC3: March | AD3: April | AE3: May | AF3: June | AG3: July | AH3: August | AI3: September | AJ3: October | AK3: November | AL3: December | AN3: January | AO3: February | AP3: March | AQ3: April | AR3: May | AS3: June | AT3: July | AU3: August | AV3: September | AW3: October | AX3: November | AY3: December | BA3: January | BB3: February | BC3: March | BD3: April | BE3: May | BF3: June | BG3: July | BH3: August | BI3: September | BJ3: October | BK3: November | BL3: December | BN3: January | BO3: February | BP3: March | BQ3: April | BR3: May | BS3: June | BT3: July | BU3: August | BV3: September | BW3: October | BX3: November | BY3: December | CA3: January | CB3: February | CC3: March | CD3: April | CE3: May | CF3: June | CG3: July | CH3: August | CI3: September | CJ3: October | CK3: November | CL3: December | CN3: January | CO3: February | CP3: March | CQ3: April | CR3: May | CS3: June | CT3: July | CU3: August | CV3: September | CW3: October | CX3: November | CY3: December | DA3: January | DB3: February | DC3: March | DD3: April | DE3: May | DF3: June | DG3: July | DH3: August | DI3: September | DJ3: October | DK3: November | DL3: December | DM3: vs | DN3: January | DO3: February | DP3: March | DQ3: April | DR3: May | DS3: June | DT3: July | DU3: August | DV3: September | DW3: October | DX3: November | DY3: December | DZ3: vs | EB3: TEST
E4: 43525 | F4: 44986 | M4: StoreID | N4: Sales 1/2023 | O4: Sales 2/2023 | P4: Sales 3/2023 | Q4: Sales 4/2023 | R4: Sales 5/2023 | S4: Sales 6/2023 | T4: Sales 7/2023 | U4: Sales 8/2023 | V4: Sales 9/2023 | W4: Sales 10/2023 | X4: Sales 11/2023 | Y4: Sales 12/2023 | Z4: YTD | AA4: Sales 1/2024 | AB4: Sales 2/2024 | AC4: Sales 3/2024 | AD4: Sales 4/2024 | AE4: Sales 5/2024 | AF4: Sales 6/2024 | AG4: Sales 7/2024 | AH4: Sales 8/2024 | AI4: Sales 9/2024 | AJ4: Sales 10/2024 | AK4: Sales 11/2024 | AL4: Sales 12/2024 | AM4: YTD | AN4: Sales 1/2025 | AO4: Sales 2/2025 | AP4: Sales 3/2025 | AQ4: Sales 4/2025 | AR4: Sales 5/2025 | AS4: Sales 6/2025 | AT4: Sales 7/2025 | AU4: Sales 8/2025 | AV4: Sales 9/2025 | AW4: Sales 10/2025 | AX4: Sales 11/2025 | AY4: Sales 12/2025 | AZ4: YTD | BA4: Price 1/2024 | BB4: Price 2/2024 | BC4: Price 3/2024 | BD4: Price 4/2024 | BE4: Price 5/2024 | BF4: Price 6/2024 | BG4: Price 7/2024 | BH4: Price 8/2024 | BI4: Price 9/2024 | BJ4: Price 10/2024 | BK4: Price 11/2024 | BL4: Price 12/2024 | BM4: YTD | BN4: Price 1/2025 | BO4: Price 2/2025 | BP4: Price 3/2025 | BQ4: Price 4/2025 | BR4: Price 5/2025 | BS4: Price 6/2025 | BT4: Price 7/2025 | BU4: Price 8/2025 | BV4: Price 9/2025 | BW4: Price 10/2025 | BX4: Price 11/2025 | BY4: Price 12/2025 | BZ4: YTD | CA4: Vol 1/2024 | CB4: Vol 2/2024 | CC4: Vol 3/2024 | CD4: Vol 4/2024 | CE4: Vol 5/2024 | CF4: Vol 6/2024 | CG4: Vol 7/2024 | CH4: Vol 8/2024 | CI4: Vol 9/2024 | CJ4: Vol 10/2024 | CK4: Vol 11/2024 | CL4: Vol 12/2024 | CM4: YTD | CN4: Vol 1/2025 | CO4: Vol 2/2025 | CP4: Vol 3/2025 | CQ4: Vol 4/2025 | CR4: Vol 5/2025 | CS4: Vol 6/2025 | CT4: Vol 7/2025 | CU4: Vol 8/2025 | CV4: Vol 9/2025 | CW4: Vol 10/2025 | CX4: Vol 11/2025 | CY4: Vol 12/2025 | CZ4: YTD | DA4: Vol Delta 1/2024 | DB4: Vol Delta 2/2024 | DC4: Vol Delta 3/2024 | DD4: Vol Delta 4/2024 | DE4: Vol Delta 5/2024 | DF4: Vol Delta 6/2024 | DG4: Vol Delta 7/2024 | DH4: Vol Delta 8/2024 | DI4: Vol Delta 9/2024 | DJ4: Vol Delta 10/2024 | DK4: Vol Delta 11/2024 | DL4: Vol Delta 12/2024 | DM4: YTD | DN4: P Delta 1/2024 | DO4: P Delta 2/2024 | DP4: P Delta 3/2024 | DQ4: P Delta 4/2024 | DR4: P Delta 5/2024 | DS4: P Delta 6/2024 | DT4: P Delta 7/2024 | DU4: P Delta 8/2024 | DV4: P Delta 9/2024 | DW4: P Delta 10/2024 | DX4: P Delta 11/2024 | DY4: P Delta 12/2024 | DZ4: YTD
